Workbook

Sheet LINHA 093 DOM
B2: 15/02/2026 - SEM COBRADOR | C2: QUADRO OPERACIONAL, DOMINGO, LINHA 093 | P2: FREQUÊNCIA DA LINHA 093
C3: 0.013888889 | D3: 1º TURNO | P3: DOMINGO
D4: TAB - 0101 | J4: TAB - 0102 | P4: =CONCATENATE(COUNT(P6:P16,R6:R16)," VIAGENS") -> 21 VIAGENS | U4: TAB - 0103 | AB4: TAB - 0202
C5: DESLOCAMENTO | D5: IDA | E5: VOLTA | F5: TÉRM. | G5: T. VIAG. | H5: LINHA | I5: VEIC. | J5: IDA | K5: VOLTA | L5: TÉRM. | M5: T. VIAG. | N5: LINHA | O5: VEIC. | P5: HORA | Q5: FREQ. | R5: HORA | S5: FREQ. | U5: IDA | V5: VOLTA | W5: TÉRM. | X5: T. VIAG. | Y5: LINHA | Z5: VEIC. | AB5: IDA | AC5: VOLTA | AD5: TÉRM. | AE5: T. VIAG. | AF5: LINHA | AG5: VEIC.
D6: 0.1875 | E6: 0.20416667 | F6: 0.22222222 | G6: =F6-D6 -> 0.034722222 | H6: 93 | I6: 1 | J6: 0.20833333 | K6: 0.22569444 | L6: 0.24375 | M6: =L6-J6 -> 0.035416667 | N6: 93 | O6: 2 | P6: 0.1875 | R6: 0.575 | S6: =R6-P16 -> 0.058333333 | U6: 0.27708333 | V6: 0.29513889 | W6: 0.31388889 | X6: =W6-U6 -> 0.036805556 | Y6: 93 | Z6: 3 | AB6: 0.71527778 | AC6: 0.73541667 | AD6: 0.75972222 | AE6: =AD6-AB6 -> 0.044444444 | AF6: 93 | AG6: 1
D7: 0.22916667 | E7: 0.24652778 | F7: 0.26458333 | G7: =F7-D7 -> 0.035416667 | H7: 93 | I7: 1 | J7: 0.25069444 | K7: 0.26875 | L7: 0.28819444 | M7: =L7-J7 -> 0.0375 | N7: 93 | O7: 2 | P7: 0.20833333 | Q7: =P7-P6 -> 0.020833333 | R7: 0.63333333 | S7: =R7-R6 -> 0.058333333 | U7: CONVENCIONAL AR | AB7: 0.77638889 | AC7: 0.79722222 | AD7: 0.81666667 | AE7: =AD7-AB7 -> 0.040277778 | AF7: 93 | AG7: 1
D8: 0.27083333 | E8: 0.29305556 | F8: 0.3125 | G8: =F8-D8 -> 0.041666667 | H8: 94 | I8: 1 | J8: 0.29861111 | K8: 0.31597222 | L8: 0.33472222 | M8: =L8-J8 -> 0.036111111 | N8: 93 | O8: 2 | P8: 0.22916667 | Q8: =P8-P7 -> 0.020833333 | R8: 0.66666667 | S8: =R8-R7 -> 0.033333333 | AB8: CONVENCIONAL AR
D9: 0.325 | E9: 0.34236111 | F9: 0.36180556 | G9: =F9-D9 -> 0.036805556 | H9: 93 | I9: 1 | J9: 0.35138889 | K9: 0.36875 | L9: 0.38819444 | M9: =L9-J9 -> 0.036805556 | N9: 93 | O9: 2 | P9: 0.25069444 | Q9: =P9-P8 -> 0.021527778 | R9: 0.69097222 | S9: =R9-R8 -> 0.024305556
D10: =IF(F9="",E9,F9) -> 0.36180556 | F10: =IF(D11="",E11,D11) -> 0.41041667 | H10: =F10-D10 -> 0.048611111 | J10: =IF(L9="",K9,L9) -> 0.38819444 | L10: =IF(J11="",K11,J11) -> 0.43680556 | N10: =L10-J10 -> 0.048611111 | P10: 0.27708333 | Q10: =P10-P9 -> 0.026388889 | R10: 0.71527778 | S10: =R10-R9 -> 0.024305556 | AB10: TAB - 0203
D11: 0.41041667 | E11: 0.43194444 | F11: 0.45277778 | G11: =F11-D11 -> 0.042361111 | H11: 93 | I11: 1 | J11: 0.43680556 | K11: 0.46527778 | L11: 0.48541667 | M11: =L11-J11 -> 0.048611111 | N11: 94 | O11: 2 | P11: 0.29861111 | Q11: =P11-P10 -> 0.021527778 | R11: 0.74583333 | S11: =R11-R10 -> 0.030555556 | AB11: IDA | AC11: VOLTA | AD11: TÉRM. | AE11: T. VIAG. | AF11: LINHA | AG11: VEIC.
D12: 0.46527778 | E12: 0.48541667 | F12: 0.50486111 | G12: =F12-D12 -> 0.039583333 | H12: 93 | I12: 1 | J12: 0.51041667 | K12: 0.53125 | L12: 0.55 | M12: =L12-J12 -> 0.039583333 | N12: 94 | O12: 2 | P12: 0.325 | Q12: =P12-P11 -> 0.026388889 | R12: 0.77638889 | S12: =R12-R11 -> 0.030555556 | AB12: 0.66666667 | AC12: 0.68958333 | AD12: 0.71180556 | AE12: 0.045138889 | AF12: 93 | AG12: 3
D13: 0.51666667 | E13: 0.53402778 | F13: 0.55347222 | G13: =F13-D13 -> 0.036805556 | H13: 93 | I13: 1 | P13: 0.35138889 | Q13: =P13-P12 -> 0.026388889 | R13: 0.85416667 | S13: =R13-R12 -> 0.077777778 | AB13: 0.88541667 | AC13: 0.90486111 | AD13: 0.92361111 | AE13: 0.038194444 | AF13: 93 | AG13: 3
D14: CONVENCIONAL AR | J14: CONVENCIONAL AR | P14: 0.41041667 | Q14: =P14-P13 -> 0.059027778 | R14: 0.88541667 | S14: =R14-R13 -> 0.03125 | AB14: 0.93055556 | AC14: 0.94861111 | AD14: 0.96597222 | AE14: 0.035416667 | AF14: 93 | AG14: 3
C15: JORN. | D15: =MAX(E6:F13)-IF(D6="",E6,D6)-MIN(H6:H12)+$C3 -> 0.33125 | H15: =OFFSET(H5,MATCH(MIN(H6:H12),H6:H12,0),-4)-IF(D6="",E6,D6)+$C3 -> 0.18819444 | J15: =MAX(K6:L13)-IF(J6="",K6,J6)-MIN(N6:N12)+$C$3 -> 0.30694444 | N15: =OFFSET(N5,MATCH(MIN(N6:N12),N6:N12,0),-4)-IF(J6="",K6,J6)+$C3 -> 0.19375 | P15: 0.46527778 | Q15: =P15-P14 -> 0.054861111 | R15: 0.93055556 | S15: =R15-R14 -> 0.045138889 | AB15: CONVENCIONAL AR
C16: 0.013888889 | D16: 2º TURNO | P16: 0.51666667 | Q16: =P16-P15 -> 0.051388889
D17: TAB - 0201
C18: DESLOCAMENTO | D18: IDA | E18: VOLTA | F18: TÉRM. | G18: T. VIAG. | H18: LINHA | I18: VEIC.
D19: 0.575 | E19: 0.59930556 | F19: 0.62083333 | G19: =F19-D19 -> 0.045833333 | H19: 93 | I19: 2
D20: 0.63333333 | E20: 0.65416667 | F20: 0.675 | G20: =F20-D20 -> 0.041666667 | H20: 93 | I20: 2
D21: 0.69097222 | E21: 0.71388889 | F21: 0.73819444 | G21: =F21-D21 -> 0.047222222 | H21: 93 | I21: 2
D22: 0.74583333 | E22: 0.76597222 | F22: 0.79027778 | G22: =F22-D22 -> 0.044444444 | H22: 93 | I22: 2
D23: =IF(F22="",E22,F22) -> 0.79027778 | F23: =IF(D24="",E24,D24) -> 0.85416667 | H23: =F23-D23 -> 0.063888889
D24: 0.85416667 | E24: 0.875 | F24: 0.89652778 | G24: =F24-D24 -> 0.042361111 | H24: 93 | I24: 2
D25: CONVENCIONAL AR
C26: JORN. | D26: =MAX(E19:F24)-IF(D19="",E19,D19)-MIN(H19:H24)+$C16 -> 0.27152778 | H26: =OFFSET(H18,MATCH(MIN(H19:H24),H19:H24,0),-4)-IF(D19="",E19,D19) -> 0.21527778
J28: VIAGEM REALIZADA POR OPERADOR DA LINHA 094

Sheet LINHA 094 DOM
B2: 15/02/2026 - SEM COBRADOR | C2: QUADRO OPERACIONAL, DOMINGO, LINHA 094 | P2: FREQUÊNCIA DA LINHA 094
C3: 0.013888889 | D3: 1º TURNO | P3: DOMINGO
D4: TAB - 0101 | P4: =CONCATENATE(COUNT(P6:P13,R6:R13)," VIAGENS") -> 15 VIAGENS | U4: TAB - 0102
C5: DESLOCAMENTO | D5: IDA | E5: VOLTA | F5: TÉRM. | G5: T. VIAG. | H5: LINHA | I5: VEIC. | P5: HORA | Q5: FREQ. | R5: HORA | S5: FREQ. | U5: IDA | V5: VOLTA | W5: TÉRM. | X5: T. VIAG. | Y5: LINHA | Z5: VEIC.
D6: 0.22222222 | E6: 0.24513889 | F6: 0.26527778 | G6: =F6-D6 -> 0.043055556 | H6: 94 | I6: 3 | P6: 0.22222222 | R6: 0.58194444 | S6: =R6-P13 -> 0.035416667 | U6: 0.27083333 | V6: 0.29305556 | W6: 0.3125 | X6: =W6-U6 -> 0.041666667 | Y6: 94 | Z6: 1
D7: 0.27708333 | E7: 0.29513889 | F7: 0.31388889 | G7: =F7-D7 -> 0.036805556 | H7: 93 | I7: 3 | P7: 0.27083333 | Q7: =P7-P6 -> 0.048611111 | R7: 0.61666667 | S7: =R7-R6 -> 0.034722222 | U7: CONVENCIONAL AR
D8: 0.31944444 | E8: 0.34305556 | F8: 0.36180556 | G8: =F8-D8 -> 0.042361111 | H8: 94 | I8: 3 | P8: 0.31944444 | Q8: =P8-P7 -> 0.048611111 | R8: 0.65138889 | S8: =R8-R7 -> 0.034722222
D9: 0.36805556 | E9: 0.39166667 | F9: 0.4125 | G9: =F9-D9 -> 0.044444444 | H9: 94 | I9: 3 | P9: 0.36805556 | Q9: =P9-P8 -> 0.048611111 | R9: 0.72291667 | S9: =R9-R8 -> 0.071527778 | U9: TAB - 0103
D10: =IF(F9="",E9,F9) -> 0.4125 | F10: =IF(D11="",E11,D11) -> 0.475 | H10: =F10-D10 -> 0.0625 | P10: 0.43680556 | Q10: =P10-P9 -> 0.06875 | R10: 0.78541667 | S10: =R10-R9 -> 0.0625 | U10: IDA | V10: VOLTA | W10: TÉRM. | X10: T. VIAG. | Y10: LINHA | Z10: VEIC.
D11: 0.475 | E11: 0.50069444 | F11: 0.52083333 | G11: =F11-D11 -> 0.045833333 | H11: 94 | I11: 3 | P11: 0.475 | Q11: =P11-P10 -> 0.038194444 | R11: 0.87152778 | S11: =R11-R10 -> 0.086111111 | U11: 0.43680556 | V11: 0.46527778 | W11: 0.48541667 | X11: =W11-U11 -> 0.048611111 | Y11: 94 | Z11: 2
D12: 0.54652778 | E12: 0.57013889 | F12: 0.59236111 | G12: =F12-D12 -> 0.045833333 | H12: 94 | I12: 3 | P12: 0.51041667 | Q12: =P12-P11 -> 0.035416667 | R12: 0.92708333 | S12: =R12-R11 -> 0.055555556 | U12: 0.51041667 | V12: 0.53125 | W12: 0.55 | X12: =W12-U12 -> 0.039583333 | Y12: 94 | Z12: 2
D13: CONVENCIONAL AR | P13: 0.54652778 | Q13: =P13-P12 -> 0.036111111 | U13: CONVENCIONAL AR
C14: JORN. | D14: =MAX(E6:F12)-IF(D6="",E6,D6)-MIN(H6:H12)+$C3 -> 0.32152778 | H14: =OFFSET(H5,MATCH(MIN(H6:H12),H6:H12,0),-4)-IF(D6="",E6,D6)+$C3 -> 0.20416667
C15: 0.013888889 | D15: 2º TURNO
D16: TAB - 0201 | J16: TAB - 0202
C17: DESLOCAMENTO | D17: IDA | E17: VOLTA | F17: TÉRM. | G17: T. VIAG. | H17: LINHA | I17: VEIC. | J17: IDA | K17: VOLTA | L17: TÉRM. | M17: T. VIAG. | N17: LINHA | O17: VEIC.
D18: 0.58194444 | E18: 0.60763889 | F18: 0.63125 | G18: =F18-D18 -> 0.049305556 | H18: 94 | I18: 1 | J18: 0.61666667 | K18: 0.63819444 | L18: 0.65902778 | M18: =L18-J18 -> 0.042361111 | N18: 94 | O18: 3
D19: 0.65138889 | E19: 0.67430556 | F19: 0.69652778 | G19: =F19-D19 -> 0.045138889 | H19: 94 | I19: 1 | J19: 0.66666667 | K19: 0.68958333 | L19: 0.71180556 | M19: =L19-J19 -> 0.045138889 | N19: 93 | O19: 3
D20: 0.71527778 | E20: 0.73541667 | F20: 0.75972222 | G20: =F20-D20 -> 0.044444444 | H20: 93 | I20: 1 | J20: 0.72291667 | K20: 0.74930556 | L20: 0.77708333 | M20: =L20-J20 -> 0.054166667 | N20: 94 | O20: 3
D21: 0.77638889 | E21: 0.79722222 | F21: 0.81666667 | G21: =F21-D21 -> 0.040277778 | H21: 93 | I21: 1 | J21: 0.78541667 | K21: 0.8125 | L21: 0.83680556 | M21: =L21-J21 -> 0.051388889 | N21: 94 | O21: 3
D22: =IF(F21="",E21,F21) -> 0.81666667 | F22: =IF(D23="",E23,D23) -> 0.87152778 | H22: =F22-D22 -> 0.054861111 | J22: =IF(L21="",K21,L21) -> 0.83680556 | L22: =IF(J23="",K23,J23) -> 0.88541667 | N22: =L22-J22 -> 0.048611111
D23: 0.87152778 | E23: 0.89375 | F23: 0.9125 | G23: =F23-D23 -> 0.040972222 | H23: 94 | I23: 1 | J23: 0.88541667 | K23: 0.90486111 | L23: 0.92361111 | M23: =L23-J23 -> 0.038194444 | N23: 93 | O23: 3
D24: 0.92708333 | E24: 0.94583333 | F24: 0.96319444 | G24: =F24-D24 -> 0.036111111 | H24: 94 | I24: 1 | J24: 0.93055556 | K24: 0.94861111 | L24: 0.96597222 | M24: =L24-J24 -> 0.035416667 | N24: 93 | O24: 3
D25: CONVENCIONAL AR | J25: CONVENCIONAL AR
C26: JORN. | D26: =MAX(E18:F24)-IF(D18="",E18,D18)-MIN(H18:H24)+$C15 -> 0.34027778 | H26: =OFFSET(H17,MATCH(MIN(H18:H24),H18:H24,0),-4)-IF(D18="",E18,D18) -> 0.23472222 | J26: =MAX(K18:L24)-IF(J18="",K18,J18)-MIN(N18:N24)+$C15 -> 0.31458333 | N26: =OFFSET(N17,MATCH(MIN(N18:N24),N18:N24,0),-4)-IF(J18="",K18,J18) -> 0.22013889
J28: VIAGEM REALIZADA POR OPERADOR DA LINHA 093

Sheet SÁB
B2: 00/00/0000 | C2: QUADRO OPERACIONAL, SÁBADO, LINHA | EF2: FREQUÊNCIA DA LINHA
C3: 0 | D3: 1º TURNO | EF3: SÁBADO
D4: TAB - 0101 | J4: TAB - 0102 | P4: TAB - 0103 | V4: TAB - 0104 | AB4: TAB - 0105 | AH4: TAB - 0106 | AN4: TAB - 0107 | AT4: TAB - 0108 | AZ4: TAB - 0109 | BF4: TAB - 0110 | BL4: TAB - 0111 | BR4: TAB - 0112 | BX4: TAB - 0113 | CD4: TAB - 0114 | CJ4: TAB - 0115 | CP4: TAB - 0116 | CV4: TAB - 0117 | DB4: TAB - 0118 | DH4: TAB - 0119 | DN4: TAB - 0120 | DT4: TAB - 0121 | DZ4: TAB - 0122 | EF4: =CONCATENATE(COUNT(EF6:EF62,EH6:EH62)," VIAGENS") -> 0 VIAGENS
C5: DESLOCAMENTO | D5: IDA | E5: VOLTA | F5: TÉRM. | G5: T. VIAG. | H5: LINHA | I5: VEIC. | J5: IDA | K5: VOLTA | L5: TÉRM. | M5: T. VIAG. | N5: LINHA | O5: VEIC. | P5: IDA | Q5: VOLTA | R5: TÉRM. | S5: T. VIAG. | T5: LINHA | U5: VEIC. | V5: IDA | W5: VOLTA | X5: TÉRM. | Y5: T. VIAG. | Z5: LINHA | AA5: VEIC. | AB5: IDA | AC5: VOLTA | AD5: TÉRM. | AE5: T. VIAG. | AF5: LINHA | AG5: VEIC. | AH5: IDA | AI5: VOLTA | AJ5: TÉRM. | AK5: T. VIAG. | AL5: LINHA | AM5: VEIC. | AN5: IDA | AO5: VOLTA | AP5: TÉRM. | AQ5: T. VIAG. | AR5: LINHA | AS5: VEIC. | AT5: IDA | AU5: VOLTA | AV5: TÉRM. | AW5: T. VIAG. | AX5: LINHA | AY5: VEIC. | AZ5: IDA | BA5: VOLTA | BB5: TÉRM. | BC5: T. VIAG. | BD5: LINHA | BE5: VEIC. | BF5: IDA | BG5: VOLTA | BH5: TÉRM. | BI5: T. VIAG. | BJ5: LINHA | BK5: VEIC. | BL5: IDA | BM5: VOLTA | BN5: TÉRM. | BO5: T. VIAG. | BP5: LINHA | BQ5: VEIC. | BR5: IDA | BS5: VOLTA | BT5: TÉRM. | BU5: T. VIAG. | BV5: LINHA | BW5: VEIC. | BX5: IDA | BY5: VOLTA | BZ5: TÉRM. | CA5: T. VIAG. | CB5: LINHA | CC5: VEIC. | CD5: IDA | CE5: VOLTA | CF5: TÉRM. | CG5: T. VIAG. | CH5: LINHA | CI5: VEIC. | CJ5: IDA | CK5: VOLTA | CL5: TÉRM. | CM5: T. VIAG. | CN5: LINHA | CO5: VEIC. | CP5: IDA | CQ5: VOLTA | CR5: TÉRM. | CS5: T. VIAG. | CT5: LINHA | CU5: VEIC. | CV5: IDA | CW5: VOLTA | CX5: TÉRM. | CY5: T. VIAG. | CZ5: LINHA | DA5: VEIC. | DB5: IDA | DC5: VOLTA | DD5: TÉRM. | DE5: T. VIAG. | DF5: LINHA | DG5: VEIC. | DH5: IDA | DI5: VOLTA | DJ5: TÉRM. | DK5: T. VIAG. | DL5: LINHA | DM5: VEIC. | DN5: IDA | DO5: VOLTA | DP5: TÉRM. | DQ5: T. VIAG. | DR5: LINHA | DS5: VEIC. | DT5: IDA | DU5: VOLTA | DV5: TÉRM. | DW5: T. VIAG. | DX5: LINHA | DY5: VEIC. | DZ5: IDA | EA5: VOLTA | EB5: TÉRM. | EC5: T. VIAG. | ED5: LINHA | EE5: VEIC. | EF5: HORA | EG5: FREQ. | EH5: HORA | EI5: FREQ.
EG7: =EF7-EF6 -> 0
D14: 0 | J14: 0 | P14: 0 | V14: 0 | AB14: 0 | AH14: 0 | AN14: 0 | AT14: 0 | AZ14: 0 | BF14: 0 | BL14: 0 | BR14: 0 | BX14: 0 | CD14: 0 | CJ14: 0 | CP14: 0 | CV14: 0 | DB14: 0 | DH14: 0 | DN14: 0 | DT14: 0 | DZ14: 0
C15: JORN. | D15: =MAX(E6:F13)-IF(D6="",E6,D6)-MIN(H6:H12)+$C3 -> 0 | H15: =OFFSET(H5,MATCH(MIN(H6:H12),H6:H12,0),-4)-IF(D6="",E6,D6)+$C3 -> #N/A | J15: =MAX(K6:L13)-IF(J6="",K6,J6)-MIN(N6:N12)+$C$3 -> 0 | N15: =OFFSET(N5,MATCH(MIN(N6:N12),N6:N12,0),-4)-IF(J6="",K6,J6)+$C3 -> #N/A | P15: =MAX(Q6:R13)-IF(P6="",Q6,P6)-MIN(T6:T12)+$C$3 -> 0 | T15: =OFFSET(T5,MATCH(MIN(T6:T12),T6:T12,0),-4)-IF(P6="",Q6,P6)+$C3 -> #N/A | V15: =MAX(W6:X13)-IF(V6="",W6,V6)-MIN(Z6:Z12)+$C$3 -> 0 | Z15: =OFFSET(Z5,MATCH(MIN(Z6:Z12),Z6:Z12,0),-4)-IF(V6="",W6,V6)+$C3 -> #N/A | AB15: =MAX(AC6:AD13)-IF(AB6="",AC6,AB6)-MIN(AF6:AF12)+$C$3 -> 0 | AF15: =OFFSET(AF5,MATCH(MIN(AF6:AF12),AF6:AF12,0),-4)-IF(AB6="",AC6,AB6)+$C3 -> #N/A | AH15: =MAX(AI6:AJ13)-IF(AH6="",AI6,AH6)-MIN(AL6:AL12)+$C$3 -> 0 | AL15: =OFFSET(AL5,MATCH(MIN(AL6:AL12),AL6:AL12,0),-4)-IF(AH6="",AI6,AH6)+$C3 -> #N/A | AN15: =MAX(AO6:AP13)-IF(AN6="",AO6,AN6)-MIN(AR6:AR12)+$C$3 -> 0 | AR15: =OFFSET(AR5,MATCH(MIN(AR6:AR12),AR6:AR12,0),-4)-IF(AN6="",AO6,AN6)+$C3 -> #N/A | AT15: =MAX(AU6:AV13)-IF(AT6="",AU6,AT6)-MIN(AX6:AX12)+$C$3 -> 0 | AX15: =OFFSET(AX5,MATCH(MIN(AX6:AX12),AX6:AX12,0),-4)-IF(AT6="",AU6,AT6)+$C3 -> #N/A | AZ15: =MAX(BA6:BB13)-IF(AZ6="",BA6,AZ6)-MIN(BD6:BD12)+$C$3 -> 0 | BD15: =OFFSET(BD5,MATCH(MIN(BD6:BD12),BD6:BD12,0),-4)-IF(AZ6="",BA6,AZ6)+$C3 -> #N/A | BF15: =MAX(BG6:BH13)-IF(BF6="",BG6,BF6)-MIN(BJ6:BJ12)+$C$3 -> 0 | BJ15: =OFFSET(BJ5,MATCH(MIN(BJ6:BJ12),BJ6:BJ12,0),-4)-IF(BF6="",BG6,BF6)+$C3 -> #N/A | BL15: =MAX(BM6:BN13)-IF(BL6="",BM6,BL6)-MIN(BP6:BP12)+$C$3 -> 0 | BP15: =OFFSET(BP5,MATCH(MIN(BP6:BP12),BP6:BP12,0),-4)-IF(BL6="",BM6,BL6)+$C3 -> #N/A | BR15: =MAX(BS6:BT13)-IF(BR6="",BS6,BR6)-MIN(BV6:BV12)+$C$3 -> 0 | BV15: =OFFSET(BV5,MATCH(MIN(BV6:BV12),BV6:BV12,0),-4)-IF(BR6="",BS6,BR6)+$C3 -> #N/A | BX15: =MAX(BY6:BZ13)-IF(BX6="",BY6,BX6)-MIN(CB6:CB12)+$C$3 -> 0 | CB15: =OFFSET(CB5,MATCH(MIN(CB6:CB12),CB6:CB12,0),-4)-IF(BX6="",BY6,BX6)+$C3 -> #N/A | CD15: =MAX(CE6:CF13)-IF(CD6="",CE6,CD6)-MIN(CH6:CH12)+$C$3 -> 0 | CH15: =OFFSET(CH5,MATCH(MIN(CH6:CH12),CH6:CH12,0),-4)-IF(CD6="",CE6,CD6)+$C3 -> #N/A | CJ15: =MAX(CK6:CL13)-IF(CJ6="",CK6,CJ6)-MIN(CN6:CN12)+$C$3 -> 0 | CN15: =OFFSET(CN5,MATCH(MIN(CN6:CN12),CN6:CN12,0),-4)-IF(CJ6="",CK6,CJ6)+$C3 -> #N/A | CP15: =MAX(CQ6:CR13)-IF(CP6="",CQ6,CP6)-MIN(CT6:CT12)+$C$3 -> 0 | CT15: =OFFSET(CT5,MATCH(MIN(CT6:CT12),CT6:CT12,0),-4)-IF(CP6="",CQ6,CP6)+$C3 -> #N/A | CV15: =MAX(CW6:CX13)-IF(CV6="",CW6,CV6)-MIN(CZ6:CZ12)+$C$3 -> 0 | CZ15: =OFFSET(CZ5,MATCH(MIN(CZ6:CZ12),CZ6:CZ12,0),-4)-IF(CV6="",CW6,CV6)+$C3 -> #N/A | DB15: =MAX(DC6:DD13)-IF(DB6="",DC6,DB6)-MIN(DF6:DF12)+$C$3 -> 0 | DF15: =OFFSET(DF5,MATCH(MIN(DF6:DF12),DF6:DF12,0),-4)-IF(DB6="",DC6,DB6)+$C3 -> #N/A | DH15: =MAX(DI6:DJ13)-IF(DH6="",DI6,DH6)-MIN(DL6:DL12)+$C$3 -> 0 | DL15: =OFFSET(DL5,MATCH(MIN(DL6:DL12),DL6:DL12,0),-4)-IF(DH6="",DI6,DH6)+$C3 -> #N/A | DN15: =MAX(DO6:DP13)-IF(DN6="",DO6,DN6)-MIN(DR6:DR12)+$C$3 -> 0 | DR15: =OFFSET(DR5,MATCH(MIN(DR6:DR12),DR6:DR12,0),-4)-IF(DN6="",DO6,DN6)+$C3 -> #N/A | DT15: =MAX(DU6:DV13)-IF(DT6="",DU6,DT6)-MIN(DX6:DX12)+$C$3 -> 0 | DX15: =OFFSET(DX5,MATCH(MIN(DX6:DX12),DX6:DX12,0),-4)-IF(DT6="",DU6,DT6)+$C3 -> #N/A | DZ15: =MAX(EA6:EB13)-IF(DZ6="",EA6,DZ6)-MIN(ED6:ED12)+$C$3 -> 0 | ED15: =OFFSET(ED5,MATCH(MIN(ED6:ED12),ED6:ED12,0),-4)-IF(DZ6="",EA6,DZ6)+$C3 -> #N/A
C16: 0 | D16: 2º TURNO
D17: TAB - 0201 | J17: TAB - 0202 | P17: TAB - 0203 | V17: TAB - 0204 | AB17: TAB - 0205 | AH17: TAB - 0206 | AN17: TAB - 0207 | AT17: TAB - 0208 | AZ17: TAB - 0209 | BF17: TAB - 0210 | BL17: TAB - 0211 | BR17: TAB - 0212 | BX17: TAB - 0213 | CD17: TAB - 0214 | CJ17: TAB - 0215 | CP17: TAB - 0216 | CV17: TAB - 0217 | DB17: TAB - 0218 | DH17: TAB - 0219 | DN17: TAB - 0220 | DT17: TAB - 0221 | DZ17: TAB - 0222
C18: DESLOCAMENTO | D18: IDA | E18: VOLTA | F18: TÉRM. | G18: T. VIAG. | H18: LINHA | I18: VEIC. | J18: IDA | K18: VOLTA | L18: TÉRM. | M18: T. VIAG. | N18: LINHA | O18: VEIC. | P18: IDA | Q18: VOLTA | R18: TÉRM. | S18: T. VIAG. | T18: LINHA | U18: VEIC. | V18: IDA | W18: VOLTA | X18: TÉRM. | Y18: T. VIAG. | Z18: LINHA | AA18: VEIC. | AB18: IDA | AC18: VOLTA | AD18: TÉRM. | AE18: T. VIAG. | AF18: LINHA | AG18: VEIC. | AH18: IDA | AI18: VOLTA | AJ18: TÉRM. | AK18: T. VIAG. | AL18: LINHA | AM18: VEIC. | AN18: IDA | AO18: VOLTA | AP18: TÉRM. | AQ18: T. VIAG. | AR18: LINHA | AS18: VEIC. | AT18: IDA | AU18: VOLTA | AV18: TÉRM. | AW18: T. VIAG. | AX18: LINHA | AY18: VEIC. | AZ18: IDA | BA18: VOLTA | BB18: TÉRM. | BC18: T. VIAG. | BD18: LINHA | BE18: VEIC. | BF18: IDA | BG18: VOLTA | BH18: TÉRM. | BI18: T. VIAG. | BJ18: LINHA | BK18: VEIC. | BL18: IDA | BM18: VOLTA | BN18: TÉRM. | BO18: T. VIAG. | BP18: LINHA | BQ18: VEIC. | BR18: IDA | BS18: VOLTA | BT18: TÉRM. | BU18: T. VIAG. | BV18: LINHA | BW18: VEIC. | BX18: IDA | BY18: VOLTA | BZ18: TÉRM. | CA18: T. VIAG. | CB18: LINHA | CC18: VEIC. | CD18: IDA | CE18: VOLTA | CF18: TÉRM. | CG18: T. VIAG. | CH18: LINHA | CI18: VEIC. | CJ18: IDA | CK18: VOLTA | CL18: TÉRM. | CM18: T. VIAG. | CN18: LINHA | CO18: VEIC. | CP18: IDA | CQ18: VOLTA | CR18: TÉRM. | CS18: T. VIAG. | CT18: LINHA | CU18: VEIC. | CV18: IDA | CW18: VOLTA | CX18: TÉRM. | CY18: T. VIAG. | CZ18: LINHA | DA18: VEIC. | DB18: IDA | DC18: VOLTA | DD18: TÉRM. | DE18: T. VIAG. | DF18: LINHA | DG18: VEIC. | DH18: IDA | DI18: VOLTA | DJ18: TÉRM. | DK18: T. VIAG. | DL18: LINHA | DM18: VEIC. | DN18: IDA | DO18: VOLTA | DP18: TÉRM. | DQ18: T. VIAG. | DR18: LINHA | DS18: VEIC. | DT18: IDA | DU18: VOLTA | DV18: TÉRM. | DW18: T. VIAG. | DX18: LINHA | DY18: VEIC. | DZ18: IDA | EA18: VOLTA | EB18: TÉRM. | EC18: T. VIAG. | ED18: LINHA | EE18: VEIC.
D27: 0 | J27: 0 | P27: 0 | V27: 0 | AB27: 0 | AH27: 0 | AN27: 0 | AT27: 0 | AZ27: 0 | BF27: 0 | BL27: 0 | BR27: 0 | BX27: 0 | CD27: 0 | CJ27: 0 | CP27: 0 | CV27: 0 | DB27: 0 | DH27: 0 | DN27: 0 | DT27: 0 | DZ27: 0
C28: JORN. | D28: =MAX(E19:F26)-IF(D19="",E19,D19)-MIN(H19:H25)+$C16 -> 0 | H28: =OFFSET(H18,MATCH(MIN(H19:H25),H19:H25,0),-4)-IF(D19="",E19,D19) -> #N/A | J28: =MAX(K19:L26)-IF(J19="",K19,J19)-MIN(N19:N25)+$C16 -> 0 | N28: =OFFSET(N18,MATCH(MIN(N19:N25),N19:N25,0),-4)-IF(J19="",K19,J19) -> #N/A | P28: =MAX(Q19:R26)-IF(P19="",Q19,P19)-MIN(T19:T25)+$C16 -> 0 | T28: =OFFSET(T18,MATCH(MIN(T19:T25),T19:T25,0),-4)-IF(P19="",Q19,P19) -> #N/A | V28: =MAX(W19:X26)-IF(V19="",W19,V19)-MIN(Z19:Z25)+$C16 -> 0 | Z28: =OFFSET(Z18,MATCH(MIN(Z19:Z25),Z19:Z25,0),-4)-IF(V19="",W19,V19) -> #N/A | AB28: =MAX(AC19:AD26)-IF(AB19="",AC19,AB19)-MIN(AF19:AF25)+$C16 -> 0 | AF28: =OFFSET(AF18,MATCH(MIN(AF19:AF25),AF19:AF25,0),-4)-IF(AB19="",AC19,AB19) -> #N/A | AH28: =MAX(AI19:AJ26)-IF(AH19="",AI19,AH19)-MIN(AL19:AL25)+$C16 -> 0 | AL28: =OFFSET(AL18,MATCH(MIN(AL19:AL25),AL19:AL25,0),-4)-IF(AH19="",AI19,AH19) -> #N/A | AN28: =MAX(AO19:AP26)-IF(AN19="",AO19,AN19)-MIN(AR19:AR25)+$C16 -> 0 | AR28: =OFFSET(AR18,MATCH(MIN(AR19:AR25),AR19:AR25,0),-4)-IF(AN19="",AO19,AN19) -> #N/A | AT28: =MAX(AU19:AV26)-IF(AT19="",AU19,AT19)-MIN(AX19:AX25)+$C16 -> 0 | AX28: =OFFSET(AX18,MATCH(MIN(AX19:AX25),AX19:AX25,0),-4)-IF(AT19="",AU19,AT19) -> #N/A | AZ28: =MAX(BA19:BB26)-IF(AZ19="",BA19,AZ19)-MIN(BD19:BD25)+$C16 -> 0 | BD28: =OFFSET(BD18,MATCH(MIN(BD19:BD25),BD19:BD25,0),-4)-IF(AZ19="",BA19,AZ19) -> #N/A | BF28: =MAX(BG19:BH26)-IF(BF19="",BG19,BF19)-MIN(BJ19:BJ25)+$C16 -> 0 | BJ28: =OFFSET(BJ18,MATCH(MIN(BJ19:BJ25),BJ19:BJ25,0),-4)-IF(BF19="",BG19,BF19) -> #N/A | BL28: =MAX(BM19:BN26)-IF(BL19="",BM19,BL19)-MIN(BP19:BP25)+$C16 -> 0 | BP28: =OFFSET(BP18,MATCH(MIN(BP19:BP25),BP19:BP25,0),-4)-IF(BL19="",BM19,BL19) -> #N/A | BR28: =MAX(BS19:BT26)-IF(BR19="",BS19,BR19)-MIN(BV19:BV25)+$C16 -> 0 | BV28: =OFFSET(BV18,MATCH(MIN(BV19:BV25),BV19:BV25,0),-4)-IF(BR19="",BS19,BR19) -> #N/A | BX28: =MAX(BY19:BZ26)-IF(BX19="",BY19,BX19)-MIN(CB19:CB25)+$C16 -> 0 | CB28: =OFFSET(CB18,MATCH(MIN(CB19:CB25),CB19:CB25,0),-4)-IF(BX19="",BY19,BX19) -> #N/A | CD28: =MAX(CE19:CF26)-IF(CD19="",CE19,CD19)-MIN(CH19:CH25)+$C16 -> 0 | CH28: =OFFSET(CH18,MATCH(MIN(CH19:CH25),CH19:CH25,0),-4)-IF(CD19="",CE19,CD19) -> #N/A | CJ28: =MAX(CK19:CL26)-IF(CJ19="",CK19,CJ19)-MIN(CN19:CN25)+$C16 -> 0 | CN28: =OFFSET(CN18,MATCH(MIN(CN19:CN25),CN19:CN25,0),-4)-IF(CJ19="",CK19,CJ19) -> #N/A | CP28: =MAX(CQ19:CR26)-IF(CP19="",CQ19,CP19)-MIN(CT19:CT25)+$C16 -> 0 | CT28: =OFFSET(CT18,MATCH(MIN(CT19:CT25),CT19:CT25,0),-4)-IF(CP19="",CQ19,CP19) -> #N/A | CV28: =MAX(CW19:CX26)-IF(CV19="",CW19,CV19)-MIN(CZ19:CZ25)+$C16 -> 0 | CZ28: =OFFSET(CZ18,MATCH(MIN(CZ19:CZ25),CZ19:CZ25,0),-4)-IF(CV19="",CW19,CV19) -> #N/A | DB28: =MAX(DC19:DD26)-IF(DB19="",DC19,DB19)-MIN(DF19:DF25)+$C16 -> 0 | DF28: =OFFSET(DF18,MATCH(MIN(DF19:DF25),DF19:DF25,0),-4)-IF(DB19="",DC19,DB19) -> #N/A | DH28: =MAX(DI19:DJ26)-IF(DH19="",DI19,DH19)-MIN(DL19:DL25)+$C16 -> 0 | DL28: =OFFSET(DL18,MATCH(MIN(DL19:DL25),DL19:DL25,0),-4)-IF(DH19="",DI19,DH19) -> #N/A | DN28: =MAX(DO19:DP26)-IF(DN19="",DO19,DN19)-MIN(DR19:DR25)+$C16 -> 0 | DR28: =OFFSET(DR18,MATCH(MIN(DR19:DR25),DR19:DR25,0),-4)-IF(DN19="",DO19,DN19) -> #N/A | DT28: =MAX(DU19:DV26)-IF(DT19="",DU19,DT19)-MIN(DX19:DX25)+$C16 -> 0 | DX28: =OFFSET(DX18,MATCH(MIN(DX19:DX25),DX19:DX25,0),-4)-IF(DT19="",DU19,DT19) -> #N/A | DZ28: =MAX(EA19:EB26)-IF(DZ19="",EA19,DZ19)-MIN(ED19:ED25)+$C16 -> 0 | ED28: =OFFSET(ED18,MATCH(MIN(ED19:ED25),ED19:ED25,0),-4)-IF(DZ19="",EA19,DZ19) -> #N/A
D31: =IF(F30="",E30,F30) -> 0 | F31: =IF(D32="",E32,D32) -> 0 | H31: =F31-D31 -> 0
E33: VIAGEM REALIZADA POR OPERADOR DA LINHA
E34: VIAGEM REALIZADA POR OPERADOR DA LINHA
E35: VIAGEM REALIZADA POR OPERADOR DA LINHA

Sheet DOM
B2: 00/00/0000 | C2: QUADRO OPERACIONAL, DOMINGO, LINHA | EF2: FREQUÊNCIA DA LINHA
C3: 0 | D3: 1º TURNO | EF3: DOMINGO
D4: TAB - 0101 | J4: TAB - 0102 | P4: TAB - 0103 | V4: TAB - 0104 | AB4: TAB - 0105 | AH4: TAB - 0106 | AN4: TAB - 0107 | AT4: TAB - 0108 | AZ4: TAB - 0109 | BF4: TAB - 0110 | BL4: TAB - 0111 | BR4: TAB - 0112 | BX4: TAB - 0113 | CD4: TAB - 0114 | CJ4: TAB - 0115 | CP4: TAB - 0116 | CV4: TAB - 0117 | DB4: TAB - 0118 | DH4: TAB - 0119 | DN4: TAB - 0120 | DT4: TAB - 0121 | DZ4: TAB - 0122 | EF4: =CONCATENATE(COUNT(EF6:EF91,EH6:EH91)," VIAGENS") -> 0 VIAGENS
C5: DESLOCAMENTO | D5: IDA | E5: VOLTA | F5: TÉRM. | G5: T. VIAG. | H5: LINHA | I5: VEIC. | J5: IDA | K5: VOLTA | L5: TÉRM. | M5: T. VIAG. | N5: LINHA | O5: VEIC. | P5: IDA | Q5: VOLTA | R5: TÉRM. | S5: T. VIAG. | T5: LINHA | U5: VEIC. | V5: IDA | W5: VOLTA | X5: TÉRM. | Y5: T. VIAG. | Z5: LINHA | AA5: VEIC. | AB5: IDA | AC5: VOLTA | AD5: TÉRM. | AE5: T. VIAG. | AF5: LINHA | AG5: VEIC. | AH5: IDA | AI5: VOLTA | AJ5: TÉRM. | AK5: T. VIAG. | AL5: LINHA | AM5: VEIC. | AN5: IDA | AO5: VOLTA | AP5: TÉRM. | AQ5: T. VIAG. | AR5: LINHA | AS5: VEIC. | AT5: IDA | AU5: VOLTA | AV5: TÉRM. | AW5: T. VIAG. | AX5: LINHA | AY5: VEIC. | AZ5: IDA | BA5: VOLTA | BB5: TÉRM. | BC5: T. VIAG. | BD5: LINHA | BE5: VEIC. | BF5: IDA | BG5: VOLTA | BH5: TÉRM. | BI5: T. VIAG. | BJ5: LINHA | BK5: VEIC. | BL5: IDA | BM5: VOLTA | BN5: TÉRM. | BO5: T. VIAG. | BP5: LINHA | BQ5: VEIC. | BR5: IDA | BS5: VOLTA | BT5: TÉRM. | BU5: T. VIAG. | BV5: LINHA | BW5: VEIC. | BX5: IDA | BY5: VOLTA | BZ5: TÉRM. | CA5: T. VIAG. | CB5: LINHA | CC5: VEIC. | CD5: IDA | CE5: VOLTA | CF5: TÉRM. | CG5: T. VIAG. | CH5: LINHA | CI5: VEIC. | CJ5: IDA | CK5: VOLTA | CL5: TÉRM. | CM5: T. VIAG. | CN5: LINHA | CO5: VEIC. | CP5: IDA | CQ5: VOLTA | CR5: TÉRM. | CS5: T. VIAG. | CT5: LINHA | CU5: VEIC. | CV5: IDA | CW5: VOLTA | CX5: TÉRM. | CY5: T. VIAG. | CZ5: LINHA | DA5: VEIC. | DB5: IDA | DC5: VOLTA | DD5: TÉRM. | DE5: T. VIAG. | DF5: LINHA | DG5: VEIC. | DH5: IDA | DI5: VOLTA | DJ5: TÉRM. | DK5: T. VIAG. | DL5: LINHA | DM5: VEIC. | DN5: IDA | DO5: VOLTA | DP5: TÉRM. | DQ5: T. VIAG. | DR5: LINHA | DS5: VEIC. | DT5: IDA | DU5: VOLTA | DV5: TÉRM. | DW5: T. VIAG. | DX5: LINHA | DY5: VEIC. | DZ5: IDA | EA5: VOLTA | EB5: TÉRM. | EC5: T. VIAG. | ED5: LINHA | EE5: VEIC. | EF5: HORA | EG5: FREQ. | EH5: HORA | EI5: FREQ.
EG7: =EF7-EF6 -> 0
D14: 0 | J14: 0 | P14: 0 | V14: 0 | AB14: 0 | AH14: 0 | AN14: 0 | AT14: 0 | AZ14: 0 | BF14: 0 | BL14: 0 | BR14: 0 | BX14: 0 | CD14: 0 | CJ14: 0 | CP14: 0 | CV14: 0 | DB14: 0 | DH14: 0 | DN14: 0 | DT14: 0 | DZ14: 0
C15: JORN. | D15: =MAX(E6:F13)-IF(D6="",E6,D6)-MIN(H6:H12)+$C3 -> 0 | H15: =OFFSET(H5,MATCH(MIN(H6:H12),H6:H12,0),-4)-IF(D6="",E6,D6)+$C3 -> #N/A | J15: =MAX(K6:L13)-IF(J6="",K6,J6)-MIN(N6:N12)+$C$3 -> 0 | N15: =OFFSET(N5,MATCH(MIN(N6:N12),N6:N12,0),-4)-IF(J6="",K6,J6)+$C3 -> #N/A | P15: =MAX(Q6:R13)-IF(P6="",Q6,P6)-MIN(T6:T12)+$C$3 -> 0 | T15: =OFFSET(T5,MATCH(MIN(T6:T12),T6:T12,0),-4)-IF(P6="",Q6,P6)+$C3 -> #N/A | V15: =MAX(W6:X13)-IF(V6="",W6,V6)-MIN(Z6:Z12)+$C$3 -> 0 | Z15: =OFFSET(Z5,MATCH(MIN(Z6:Z12),Z6:Z12,0),-4)-IF(V6="",W6,V6)+$C3 -> #N/A | AB15: =MAX(AC6:AD13)-IF(AB6="",AC6,AB6)-MIN(AF6:AF12)+$C$3 -> 0 | AF15: =OFFSET(AF5,MATCH(MIN(AF6:AF12),AF6:AF12,0),-4)-IF(AB6="",AC6,AB6)+$C3 -> #N/A | AH15: =MAX(AI6:AJ13)-IF(AH6="",AI6,AH6)-MIN(AL6:AL12)+$C$3 -> 0 | AL15: =OFFSET(AL5,MATCH(MIN(AL6:AL12),AL6:AL12,0),-4)-IF(AH6="",AI6,AH6)+$C3 -> #N/A | AN15: =MAX(AO6:AP13)-IF(AN6="",AO6,AN6)-MIN(AR6:AR12)+$C$3 -> 0 | AR15: =OFFSET(AR5,MATCH(MIN(AR6:AR12),AR6:AR12,0),-4)-IF(AN6="",AO6,AN6)+$C3 -> #N/A | AT15: =MAX(AU6:AV13)-IF(AT6="",AU6,AT6)-MIN(AX6:AX12)+$C$3 -> 0 | AX15: =OFFSET(AX5,MATCH(MIN(AX6:AX12),AX6:AX12,0),-4)-IF(AT6="",AU6,AT6)+$C3 -> #N/A | AZ15: =MAX(BA6:BB13)-IF(AZ6="",BA6,AZ6)-MIN(BD6:BD12)+$C$3 -> 0 | BD15: =OFFSET(BD5,MATCH(MIN(BD6:BD12),BD6:BD12,0),-4)-IF(AZ6="",BA6,AZ6)+$C3 -> #N/A | BF15: =MAX(BG6:BH13)-IF(BF6="",BG6,BF6)-MIN(BJ6:BJ12)+$C$3 -> 0 | BJ15: =OFFSET(BJ5,MATCH(MIN(BJ6:BJ12),BJ6:BJ12,0),-4)-IF(BF6="",BG6,BF6)+$C3 -> #N/A | BL15: =MAX(BM6:BN13)-IF(BL6="",BM6,BL6)-MIN(BP6:BP12)+$C$3 -> 0 | BP15: =OFFSET(BP5,MATCH(MIN(BP6:BP12),BP6:BP12,0),-4)-IF(BL6="",BM6,BL6)+$C3 -> #N/A | BR15: =MAX(BS6:BT13)-IF(BR6="",BS6,BR6)-MIN(BV6:BV12)+$C$3 -> 0 | BV15: =OFFSET(BV5,MATCH(MIN(BV6:BV12),BV6:BV12,0),-4)-IF(BR6="",BS6,BR6)+$C3 -> #N/A | BX15: =MAX(BY6:BZ13)-IF(BX6="",BY6,BX6)-MIN(CB6:CB12)+$C$3 -> 0 | CB15: =OFFSET(CB5,MATCH(MIN(CB6:CB12),CB6:CB12,0),-4)-IF(BX6="",BY6,BX6)+$C3 -> #N/A | CD15: =MAX(CE6:CF13)-IF(CD6="",CE6,CD6)-MIN(CH6:CH12)+$C$3 -> 0 | CH15: =OFFSET(CH5,MATCH(MIN(CH6:CH12),CH6:CH12,0),-4)-IF(CD6="",CE6,CD6)+$C3 -> #N/A | CJ15: =MAX(CK6:CL13)-IF(CJ6="",CK6,CJ6)-MIN(CN6:CN12)+$C$3 -> 0 | CN15: =OFFSET(CN5,MATCH(MIN(CN6:CN12),CN6:CN12,0),-4)-IF(CJ6="",CK6,CJ6)+$C3 -> #N/A | CP15: =MAX(CQ6:CR13)-IF(CP6="",CQ6,CP6)-MIN(CT6:CT12)+$C$3 -> 0 | CT15: =OFFSET(CT5,MATCH(MIN(CT6:CT12),CT6:CT12,0),-4)-IF(CP6="",CQ6,CP6)+$C3 -> #N/A | CV15: =MAX(CW6:CX13)-IF(CV6="",CW6,CV6)-MIN(CZ6:CZ12)+$C$3 -> 0 | CZ15: =OFFSET(CZ5,MATCH(MIN(CZ6:CZ12),CZ6:CZ12,0),-4)-IF(CV6="",CW6,CV6)+$C3 -> #N/A | DB15: =MAX(DC6:DD13)-IF(DB6="",DC6,DB6)-MIN(DF6:DF12)+$C$3 -> 0 | DF15: =OFFSET(DF5,MATCH(MIN(DF6:DF12),DF6:DF12,0),-4)-IF(DB6="",DC6,DB6)+$C3 -> #N/A | DH15: =MAX(DI6:DJ13)-IF(DH6="",DI6,DH6)-MIN(DL6:DL12)+$C$3 -> 0 | DL15: =OFFSET(DL5,MATCH(MIN(DL6:DL12),DL6:DL12,0),-4)-IF(DH6="",DI6,DH6)+$C3 -> #N/A | DN15: =MAX(DO6:DP13)-IF(DN6="",DO6,DN6)-MIN(DR6:DR12)+$C$3 -> 0 | DR15: =OFFSET(DR5,MATCH(MIN(DR6:DR12),DR6:DR12,0),-4)-IF(DN6="",DO6,DN6)+$C3 -> #N/A | DT15: =MAX(DU6:DV13)-IF(DT6="",DU6,DT6)-MIN(DX6:DX12)+$C$3 -> 0 | DX15: =OFFSET(DX5,MATCH(MIN(DX6:DX12),DX6:DX12,0),-4)-IF(DT6="",DU6,DT6)+$C3 -> #N/A | DZ15: =MAX(EA6:EB13)-IF(DZ6="",EA6,DZ6)-MIN(ED6:ED12)+$C$3 -> 0 | ED15: =OFFSET(ED5,MATCH(MIN(ED6:ED12),ED6:ED12,0),-4)-IF(DZ6="",EA6,DZ6)+$C3 -> #N/A
C16: 0 | D16: 2º TURNO
D17: TAB - 0201 | J17: TAB - 0202 | P17: TAB - 0203 | V17: TAB - 0204 | AB17: TAB - 0205 | AH17: TAB - 0206 | AN17: TAB - 0207 | AT17: TAB - 0208 | AZ17: TAB - 0209 | BF17: TAB - 0210 | BL17: TAB - 0211 | BR17: TAB - 0212 | BX17: TAB - 0213 | CD17: TAB - 0214 | CJ17: TAB - 0215 | CP17: TAB - 0216 | CV17: TAB - 0217 | DB17: TAB - 0218 | DH17: TAB - 0219 | DN17: TAB - 0220 | DT17: TAB - 0221 | DZ17: TAB - 0222
C18: DESLOCAMENTO | D18: IDA | E18: VOLTA | F18: TÉRM. | G18: T. VIAG. | H18: LINHA | I18: VEIC. | J18: IDA | K18: VOLTA | L18: TÉRM. | M18: T. VIAG. | N18: LINHA | O18: VEIC. | P18: IDA | Q18: VOLTA | R18: TÉRM. | S18: T. VIAG. | T18: LINHA | U18: VEIC. | V18: IDA | W18: VOLTA | X18: TÉRM. | Y18: T. VIAG. | Z18: LINHA | AA18: VEIC. | AB18: IDA | AC18: VOLTA | AD18: TÉRM. | AE18: T. VIAG. | AF18: LINHA | AG18: VEIC. | AH18: IDA | AI18: VOLTA | AJ18: TÉRM. | AK18: T. VIAG. | AL18: LINHA | AM18: VEIC. | AN18: IDA | AO18: VOLTA | AP18: TÉRM. | AQ18: T. VIAG. | AR18: LINHA | AS18: VEIC. | AT18: IDA | AU18: VOLTA | AV18: TÉRM. | AW18: T. VIAG. | AX18: LINHA | AY18: VEIC. | AZ18: IDA | BA18: VOLTA | BB18: TÉRM. | BC18: T. VIAG. | BD18: LINHA | BE18: VEIC. | BF18: IDA | BG18: VOLTA | BH18: TÉRM. | BI18: T. VIAG. | BJ18: LINHA | BK18: VEIC. | BL18: IDA | BM18: VOLTA | BN18: TÉRM. | BO18: T. VIAG. | BP18: LINHA | BQ18: VEIC. | BR18: IDA | BS18: VOLTA | BT18: TÉRM. | BU18: T. VIAG. | BV18: LINHA | BW18: VEIC. | BX18: IDA | BY18: VOLTA | BZ18: TÉRM. | CA18: T. VIAG. | CB18: LINHA | CC18: VEIC. | CD18: IDA | CE18: VOLTA | CF18: TÉRM. | CG18: T. VIAG. | CH18: LINHA | CI18: VEIC. | CJ18: IDA | CK18: VOLTA | CL18: TÉRM. | CM18: T. VIAG. | CN18: LINHA | CO18: VEIC. | CP18: IDA | CQ18: VOLTA | CR18: TÉRM. | CS18: T. VIAG. | CT18: LINHA | CU18: VEIC. | CV18: IDA | CW18: VOLTA | CX18: TÉRM. | CY18: T. VIAG. | CZ18: LINHA | DA18: VEIC. | DB18: IDA | DC18: VOLTA | DD18: TÉRM. | DE18: T. VIAG. | DF18: LINHA | DG18: VEIC. | DH18: IDA | DI18: VOLTA | DJ18: TÉRM. | DK18: T. VIAG. | DL18: LINHA | DM18: VEIC. | DN18: IDA | DO18: VOLTA | DP18: TÉRM. | DQ18: T. VIAG. | DR18: LINHA | DS18: VEIC. | DT18: IDA | DU18: VOLTA | DV18: TÉRM. | DW18: T. VIAG. | DX18: LINHA | DY18: VEIC. | DZ18: IDA | EA18: VOLTA | EB18: TÉRM. | EC18: T. VIAG. | ED18: LINHA | EE18: VEIC.
D27: 0 | J27: 0 | P27: 0 | V27: 0 | AB27: 0 | AH27: 0 | AN27: 0 | AT27: 0 | AZ27: 0 | BF27: 0 | BL27: 0 | BR27: 0 | BX27: 0 | CD27: 0 | CJ27: 0 | CP27: 0 | CV27: 0 | DB27: 0 | DH27: 0 | DN27: 0 | DT27: 0 | DZ27: 0
C28: JORN. | D28: =MAX(E19:F26)-IF(D19="",E19,D19)-MIN(H19:H25)+$C16 -> 0 | H28: =OFFSET(H18,MATCH(MIN(H19:H25),H19:H25,0),-4)-IF(D19="",E19,D19) -> #N/A | J28: =MAX(K19:L26)-IF(J19="",K19,J19)-MIN(N19:N25)+$C16 -> 0 | N28: =OFFSET(N18,MATCH(MIN(N19:N25),N19:N25,0),-4)-IF(J19="",K19,J19) -> #N/A | P28: =MAX(Q19:R26)-IF(P19="",Q19,P19)-MIN(T19:T25)+$C16 -> 0 | T28: =OFFSET(T18,MATCH(MIN(T19:T25),T19:T25,0),-4)-IF(P19="",Q19,P19) -> #N/A | V28: =MAX(W19:X26)-IF(V19="",W19,V19)-MIN(Z19:Z25)+$C16 -> 0 | Z28: =OFFSET(Z18,MATCH(MIN(Z19:Z25),Z19:Z25,0),-4)-IF(V19="",W19,V19) -> #N/A | AB28: =MAX(AC19:AD26)-IF(AB19="",AC19,AB19)-MIN(AF19:AF25)+$C16 -> 0 | AF28: =OFFSET(AF18,MATCH(MIN(AF19:AF25),AF19:AF25,0),-4)-IF(AB19="",AC19,AB19) -> #N/A | AH28: =MAX(AI19:AJ26)-IF(AH19="",AI19,AH19)-MIN(AL19:AL25)+$C16 -> 0 | AL28: =OFFSET(AL18,MATCH(MIN(AL19:AL25),AL19:AL25,0),-4)-IF(AH19="",AI19,AH19) -> #N/A | AN28: =MAX(AO19:AP26)-IF(AN19="",AO19,AN19)-MIN(AR19:AR25)+$C16 -> 0 | AR28: =OFFSET(AR18,MATCH(MIN(AR19:AR25),AR19:AR25,0),-4)-IF(AN19="",AO19,AN19) -> #N/A | AT28: =MAX(AU19:AV26)-IF(AT19="",AU19,AT19)-MIN(AX19:AX25)+$C16 -> 0 | AX28: =OFFSET(AX18,MATCH(MIN(AX19:AX25),AX19:AX25,0),-4)-IF(AT19="",AU19,AT19) -> #N/A | AZ28: =MAX(BA19:BB26)-IF(AZ19="",BA19,AZ19)-MIN(BD19:BD25)+$C16 -> 0 | BD28: =OFFSET(BD18,MATCH(MIN(BD19:BD25),BD19:BD25,0),-4)-IF(AZ19="",BA19,AZ19) -> #N/A | BF28: =MAX(BG19:BH26)-IF(BF19="",BG19,BF19)-MIN(BJ19:BJ25)+$C16 -> 0 | BJ28: =OFFSET(BJ18,MATCH(MIN(BJ19:BJ25),BJ19:BJ25,0),-4)-IF(BF19="",BG19,BF19) -> #N/A | BL28: =MAX(BM19:BN26)-IF(BL19="",BM19,BL19)-MIN(BP19:BP25)+$C16 -> 0 | BP28: =OFFSET(BP18,MATCH(MIN(BP19:BP25),BP19:BP25,0),-4)-IF(BL19="",BM19,BL19) -> #N/A | BR28: =MAX(BS19:BT26)-IF(BR19="",BS19,BR19)-MIN(BV19:BV25)+$C16 -> 0 | BV28: =OFFSET(BV18,MATCH(MIN(BV19:BV25),BV19:BV25,0),-4)-IF(BR19="",BS19,BR19) -> #N/A | BX28: =MAX(BY19:BZ26)-IF(BX19="",BY19,BX19)-MIN(CB19:CB25)+$C16 -> 0 | CB28: =OFFSET(CB18,MATCH(MIN(CB19:CB25),CB19:CB25,0),-4)-IF(BX19="",BY19,BX19) -> #N/A | CD28: =MAX(CE19:CF26)-IF(CD19="",CE19,CD19)-MIN(CH19:CH25)+$C16 -> 0 | CH28: =OFFSET(CH18,MATCH(MIN(CH19:CH25),CH19:CH25,0),-4)-IF(CD19="",CE19,CD19) -> #N/A | CJ28: =MAX(CK19:CL26)-IF(CJ19="",CK19,CJ19)-MIN(CN19:CN25)+$C16 -> 0 | CN28: =OFFSET(CN18,MATCH(MIN(CN19:CN25),CN19:CN25,0),-4)-IF(CJ19="",CK19,CJ19) -> #N/A | CP28: =MAX(CQ19:CR26)-IF(CP19="",CQ19,CP19)-MIN(CT19:CT25)+$C16 -> 0 | CT28: =OFFSET(CT18,MATCH(MIN(CT19:CT25),CT19:CT25,0),-4)-IF(CP19="",CQ19,CP19) -> #N/A | CV28: =MAX(CW19:CX26)-IF(CV19="",CW19,CV19)-MIN(CZ19:CZ25)+$C16 -> 0 | CZ28: =OFFSET(CZ18,MATCH(MIN(CZ19:CZ25),CZ19:CZ25,0),-4)-IF(CV19="",CW19,CV19) -> #N/A | DB28: =MAX(DC19:DD26)-IF(DB19="",DC19,DB19)-MIN(DF19:DF25)+$C16 -> 0 | DF28: =OFFSET(DF18,MATCH(MIN(DF19:DF25),DF19:DF25,0),-4)-IF(DB19="",DC19,DB19) -> #N/A | DH28: =MAX(DI19:DJ26)-IF(DH19="",DI19,DH19)-MIN(DL19:DL25)+$C16 -> 0 | DL28: =OFFSET(DL18,MATCH(MIN(DL19:DL25),DL19:DL25,0),-4)-IF(DH19="",DI19,DH19) -> #N/A | DN28: =MAX(DO19:DP26)-IF(DN19="",DO19,DN19)-MIN(DR19:DR25)+$C16 -> 0 | DR28: =OFFSET(DR18,MATCH(MIN(DR19:DR25),DR19:DR25,0),-4)-IF(DN19="",DO19,DN19) -> #N/A | DT28: =MAX(DU19:DV26)-IF(DT19="",DU19,DT19)-MIN(DX19:DX25)+$C16 -> 0 | DX28: =OFFSET(DX18,MATCH(MIN(DX19:DX25),DX19:DX25,0),-4)-IF(DT19="",DU19,DT19) -> #N/A | DZ28: =MAX(EA19:EB26)-IF(DZ19="",EA19,DZ19)-MIN(ED19:ED25)+$C16 -> 0 | ED28: =OFFSET(ED18,MATCH(MIN(ED19:ED25),ED19:ED25,0),-4)-IF(DZ19="",EA19,DZ19) -> #N/A
D31: =IF(F30="",E30,F30) -> 0 | F31: =IF(D32="",E32,D32) -> 0 | H31: =F31-D31 -> 0
E33: VIAGEM REALIZADA POR OPERADOR DA LINHA
E34: VIAGEM REALIZADA POR OPERADOR DA LINHA
E35: VIAGEM REALIZADA POR OPERADOR DA LINHA

Sheet DIGITAÇÃO
B2: 0.1875 | C2: 0.20416667 | D2: 0.22222222 | E2: =D2-B2 -> 0.034722222 | F2: 93 | G2: 1 | H2: 0.20833333 | I2: 0.22569444 | J2: 0.24375 | K2: =J2-H2 -> 0.035416667 | L2: 93 | M2: 2
B3: 0.22916667 | C3: 0.24652778 | D3: 0.26458333 | E3: =D3-B3 -> 0.035416667 | F3: 93 | G3: 1 | H3: 0.25069444 | I3: 0.26875 | J3: 0.28819444 | K3: =J3-H3 -> 0.0375 | L3: 93 | M3: 2
B4: 0.27083333 | C4: 0.29305556 | D4: 0.3125 | E4: =D4-B4 -> 0.041666667 | F4: 94 | G4: 1 | H4: 0.29861111 | I4: 0.31597222 | J4: 0.33472222 | K4: =J4-H4 -> 0.036111111 | L4: 93 | M4: 2
B5: 0.325 | C5: 0.34236111 | D5: 0.36180556 | E5: =D5-B5 -> 0.036805556 | F5: 93 | G5: 1 | H5: 0.35138889 | I5: 0.36875 | J5: 0.38819444 | K5: =J5-H5 -> 0.036805556 | L5: 93 | M5: 2
B6: =IF(D5="",C5,D5) -> 0.36180556 | D6: =IF(B7="",C7,B7) -> 0.41041667 | F6: =D6-B6 -> 0.048611111 | H6: =IF(J5="",I5,J5) -> 0.38819444 | J6: =IF(H7="",I7,H7) -> 0.43680556 | L6: =J6-H6 -> 0.048611111
B7: 0.41041667 | C7: 0.43194444 | D7: 0.45277778 | E7: =D7-B7 -> 0.042361111 | F7: 93 | G7: 1 | H7: 0.43680556 | I7: 0.46527778 | J7: 0.48541667 | K7: =J7-H7 -> 0.048611111 | L7: 94 | M7: 2
B8: 0.46527778 | C8: 0.48541667 | D8: 0.50486111 | E8: =D8-B8 -> 0.039583333 | F8: 93 | G8: 1 | H8: 0.51041667 | I8: 0.53125 | J8: 0.55 | K8: =J8-H8 -> 0.039583333 | L8: 94 | M8: 2
B9: 0.51666667 | C9: 0.53402778 | D9: 0.55347222 | E9: =D9-B9 -> 0.036805556 | F9: 93 | G9: 1
B12: 0.575 | C12: 0.59930556 | D12: 0.62083333 | E12: =D12-B12 -> 0.045833333 | F12: 93 | G12: 2
B13: 0.63333333 | C13: 0.65416667 | D13: 0.675 | E13: =D13-B13 -> 0.041666667 | F13: 93 | G13: 2
B14: 0.69097222 | C14: 0.71388889 | D14: 0.73819444 | E14: =D14-B14 -> 0.047222222 | F14: 93 | G14: 2
B15: 0.74583333 | C15: 0.76597222 | D15: 0.79027778 | E15: =D15-B15 -> 0.044444444 | F15: 93 | G15: 2
B16: =IF(D15="",C15,D15) -> 0.79027778 | D16: =IF(B17="",C17,B17) -> 0.85416667 | F16: =D16-B16 -> 0.063888889
B17: 0.85416667 | C17: 0.875 | D17: 0.89652778 | E17: =D17-B17 -> 0.042361111 | F17: 93 | G17: 2
B23: 0.22222222 | C23: 0.24513889 | D23: 0.26527778 | E23: =D23-B23 -> 0.043055556 | F23: 94 | G23: 3
B24: 0.27708333 | C24: 0.29513889 | D24: 0.31388889 | E24: =D24-B24 -> 0.036805556 | F24: 93 | G24: 3
B25: 0.31944444 | C25: 0.34305556 | D25: 0.36180556 | E25: =D25-B25 -> 0.042361111 | F25: 94 | G25: 3
B26: 0.36805556 | C26: 0.39166667 | D26: 0.4125 | E26: =D26-B26 -> 0.044444444 | F26: 94 | G26: 3
B27: =IF(D26="",C26,D26) -> 0.4125 | D27: =IF(B28="",C28,B28) -> 0.475 | F27: =D27-B27 -> 0.0625
B28: 0.475 | C28: 0.50069444 | D28: 0.52083333 | E28: =D28-B28 -> 0.045833333 | F28: 94 | G28: 3
B29: 0.54652778 | C29: 0.57013889 | D29: 0.59236111 | E29: =D29-B29 -> 0.045833333 | F29: 94 | G29: 3
B32: 0.58194444 | C32: 0.60763889 | D32: 0.63125 | E32: =D32-B32 -> 0.049305556 | F32: 94 | G32: 1 | H32: 0.61666667 | I32: 0.63819444 | J32: 0.65902778 | K32: =J32-H32 -> 0.042361111 | L32: 94 | M32: 3
B33: 0.65138889 | C33: 0.67430556 | D33: 0.69652778 | E33: =D33-B33 -> 0.045138889 | F33: 94 | G33: 1 | H33: 0.66666667 | I33: 0.68958333 | J33: 0.71180556 | K33: =J33-H33 -> 0.045138889 | L33: 93 | M33: 3
B34: 0.71527778 | C34: 0.73541667 | D34: 0.75972222 | E34: =D34-B34 -> 0.044444444 | F34: 93 | G34: 1 | H34: 0.72291667 | I34: 0.74930556 | J34: 0.77708333 | K34: =J34-H34 -> 0.054166667 | L34: 94 | M34: 3
B35: 0.77638889 | C35: 0.79722222 | D35: 0.81666667 | E35: =D35-B35 -> 0.040277778 | F35: 93 | G35: 1 | H35: 0.78541667 | I35: 0.8125 | J35: 0.83680556 | K35: =J35-H35 -> 0.051388889 | L35: 94 | M35: 3
B36: =IF(D35="",C35,D35) -> 0.81666667 | D36: =IF(B37="",C37,B37) -> 0.87152778 | F36: =D36-B36 -> 0.054861111 | H36: =IF(J35="",I35,J35) -> 0.83680556 | J36: =IF(H37="",I37,H37) -> 0.88541667 | L36: =J36-H36 -> 0.048611111
B37: 0.87152778 | C37: 0.89375 | D37: 0.9125 | E37: =D37-B37 -> 0.040972222 | F37: 94 | G37: 1 | H37: 0.88541667 | I37: 0.90486111 | J37: 0.92361111 | K37: =J37-H37 -> 0.038194444 | L37: 93 | M37: 3
B38: 0.92708333 | C38: 0.94583333 | D38: 0.96319444 | E38: =D38-B38 -> 0.036111111 | F38: 94 | G38: 1 | H38: 0.93055556 | I38: 0.94861111 | J38: 0.96597222 | K38: =J38-H38 -> 0.035416667 | L38: 93 | M38: 3
B49: 0.1875 | E49: 0.22222222
B50: 0.20833333 | E50: 0.27083333
B51: 0.22916667 | E51: 0.31944444
B52: 0.25069444 | E52: 0.36805556
B53: 0.27708333 | E53: 0.43680556
B54: 0.29861111 | E54: 0.475
B55: 0.325 | E55: 0.51041667
B56: 0.35138889 | E56: 0.54652778
B57: 0.41041667 | E57: 0.58194444
B58: 0.46527778 | E58: 0.61666667
B59: 0.51666667 | E59: 0.65138889
B60: 0.575 | E60: 0.72291667
...

Sheet DADOS CSV
H1: TURNO | J1: =IF(B1<0.458333333333333,CONCATENATE(A1,".","1 - TU"),CONCATENATE(A1,".","2 - TU")) -> .1 - TU | K1: Ida | N1: Volta
A2: Trip | B2: Ida | C2: Volta | D2: Térm | E2: T. Viag | F2: Linha | G2: Veíc | H2: 1 | J2: Tab | K2: Início | L2: Térm. | N2: Início | O2: Térm.
H3: =H2 -> 1 | J3: {=IF(H3=1,CONCATENATE(A3,".",H3),CONCATENATE(A3-(MAX(IF(H:H=1,A:A,))),".",H3))} -> .1 | K3: =IF($A3="","",(IF($C3-$B3<0.0007,"*****",B3))) | L3: =IF($A3="","",(IF($C3-$B3<0.0007,"*****",C3))) | N3: =IF($A3="","",(IF($D3-$C3<0.0007,"*****",C3))) | O3: =IF($A3="","",(IF($D3-$C3<0.0007,"*****",D3)))
H4: =H3 -> 1
H5: =H4 -> 1
H6: =H5 -> 1
H7: =H6 -> 1
H8: =H7 -> 1
H9: =H8 -> 1
H10: =H9 -> 1
H11: =H10 -> 1
H12: =H11 -> 1
H13: =H12 -> 1
H14: =H13 -> 1
H15: =H14 -> 1
... H200: =H199 -> 1

Sheet CSV IDA
A1: Tabela | B1: Horario_Partida | C1: Tolerancia_Atraso1 | D1: Tolerancia_Adiantamento1 | E1: Horario_Chegada | F1: Tolerancia_Atraso2 | G1: Tolerancia_Adiantamento2 | H1: ponto1 | I1: passagem1 | J1: permanencia1 | K1: ponto2 | L1: passagem2 | M1: permanencia2 | N1: ponto3 | O1: passagem3 | P1: permanencia3 | Q1: ponto4 | R1: passagem4 | S1: permanencia4 | T1: ponto5 | U1: passagem5 | V1: permanencia5 | W1: ponto6 | X1: passagem6 | Y1: permanencia6 | Z1: ponto7 | AA1: passagem7 | AB1: permanencia7 | AC1: ponto8 | AD1: passagem8 | AE1: permanencia8 | AF1: ponto9 | AG1: passagem9 | AH1: permanencia9 | AI1: ponto10 | AJ1: passagem10 | AK1: permanencia10 | AL1: ponto11 | AM1: passagem11 | AN1: permanencia11 | AO1: ponto12 | AP1: passagem12 | AQ1: permanencia12 | AR1: ponto13 | AS1: passagem13 | AT1: permanencia13 | AU1: ponto14 | AV1: passagem14 | AW1: permanencia14 | AX1: ponto15 | AY1: passagem15 | AZ1: permanencia15 | BA1: ponto16 | BB1: passagem16 | BC1: permanencia16 | BD1: ponto17 | BE1: passagem17 | BF1: permanencia17 | BG1: ponto18 | BH1: passagem18 | BI1: permanencia18 | BJ1: ponto19 | BK1: passagem19 | BL1: permanencia19 | BM1: ponto20 | BN1: passagem20 | BO1: permanencia20 | BP1: ponto21 | BQ1: passagem21 | BR1: permanencia21 | BS1: ponto22 | BT1: passagem22 | BU1: permanencia22 | BV1: ponto23 | BW1: passagem23 | BX1: permanencia23 | BY1: ponto24 | BZ1: passagem24 | CA1: permanencia24 | CB1: ponto25 | CC1: passagem25 | CD1: permanencia25 | CE1: ponto26 | CF1: passagem26 | CG1: permanencia26 | CH1: ponto27 | CI1: passagem27 | CJ1: permanencia27 | CK1: ponto28 | CL1: passagem28 | CM1: permanencia28 | CN1: ponto29 | CO1: passagem29 | CP1: permanencia29 | CQ1: ponto30 | CR1: passagem30 | CS1: permanencia30 | CT1: empresa | CU1: cod_modelo_veiculo
A2: =IF('DADOS CSV'!J3="","",'DADOS CSV'!J3) -> .1 | B2: =IF('DADOS CSV'!K3="","",'DADOS CSV'!K3) | C2: 9 | D2: 1 | E2: =IF('DADOS CSV'!L3="","",'DADOS CSV'!L3) | F2: 15 | G2: 10 | CT2: XXX | CU2: =IFERROR(VLOOKUP(Procv!Q2,Procv!$C$1:$D$21,2,0),"")
A3: =IF('DADOS CSV'!J4="","",'DADOS CSV'!J4) | B3: =IF('DADOS CSV'!K4="","",'DADOS CSV'!K4) | C3: =IF(A3="","",$C$2) | D3: =IF(A3="","",$D$2) | E3: =IF('DADOS CSV'!L4="","",'DADOS CSV'!L4) | F3: =IF(A3="","",$F$2) | G3: =IF(A3="","",$G$2) | CT3: =IF(A3="","",$CT$2) | CU3: =IFERROR(VLOOKUP(Procv!Q3,Procv!$C$1:$D$21,2,0),"")
A4: =IF('DADOS CSV'!J5="","",'DADOS CSV'!J5) | B4: =IF('DADOS CSV'!K5="","",'DADOS CSV'!K5) | C4: =IF(A4="","",$C$2) | D4: =IF(A4="","",$D$2) | E4: =IF('DADOS CSV'!L5="","",'DADOS CSV'!L5) | F4: =IF(A4="","",$F$2) | G4: =IF(A4="","",$G$2) | CT4: =IF(A4="","",$CT$2) | CU4: =IFERROR(VLOOKUP(Procv!Q4,Procv!$C$1:$D$21,2,0),"")
A5: =IF('DADOS CSV'!J6="","",'DADOS CSV'!J6) | B5: =IF('DADOS CSV'!K6="","",'DADOS CSV'!K6) | C5: =IF(A5="","",$C$2) | D5: =IF(A5="","",$D$2) | E5: =IF('DADOS CSV'!L6="","",'DADOS CSV'!L6) | F5: =IF(A5="","",$F$2) | G5: =IF(A5="","",$G$2) | CT5: =IF(A5="","",$CT$2) | CU5: =IFERROR(VLOOKUP(Procv!Q5,Procv!$C$1:$D$21,2,0),"")
A6: =IF('DADOS CSV'!J7="","",'DADOS CSV'!J7) | B6: =IF('DADOS CSV'!K7="","",'DADOS CSV'!K7) | C6: =IF(A6="","",$C$2) | D6: =IF(A6="","",$D$2) | E6: =IF('DADOS CSV'!L7="","",'DADOS CSV'!L7) | F6: =IF(A6="","",$F$2) | G6: =IF(A6="","",$G$2) | CT6: =IF(A6="","",$CT$2) | CU6: =IFERROR(VLOOKUP(Procv!Q6,Procv!$C$1:$D$21,2,0),"")
A7: =IF('DADOS CSV'!J8="","",'DADOS CSV'!J8) | B7: =IF('DADOS CSV'!K8="","",'DADOS CSV'!K8) | C7: =IF(A7="","",$C$2) | D7: =IF(A7="","",$D$2) | E7: =IF('DADOS CSV'!L8="","",'DADOS CSV'!L8) | F7: =IF(A7="","",$F$2) | G7: =IF(A7="","",$G$2) | CT7: =IF(A7="","",$CT$2) | CU7: =IFERROR(VLOOKUP(Procv!Q7,Procv!$C$1:$D$21,2,0),"")
A8: =IF('DADOS CSV'!J9="","",'DADOS CSV'!J9) | B8: =IF('DADOS CSV'!K9="","",'DADOS CSV'!K9) | C8: =IF(A8="","",$C$2) | D8: =IF(A8="","",$D$2) | E8: =IF('DADOS CSV'!L9="","",'DADOS CSV'!L9) | F8: =IF(A8="","",$F$2) | G8: =IF(A8="","",$G$2) | CT8: =IF(A8="","",$CT$2) | CU8: =IFERROR(VLOOKUP(Procv!Q8,Procv!$C$1:$D$21,2,0),"")
A9: =IF('DADOS CSV'!J10="","",'DADOS CSV'!J10) | B9: =IF('DADOS CSV'!K10="","",'DADOS CSV'!K10) | C9: =IF(A9="","",$C$2) | D9: =IF(A9="","",$D$2) | E9: =IF('DADOS CSV'!L10="","",'DADOS CSV'!L10) | F9: =IF(A9="","",$F$2) | G9: =IF(A9="","",$G$2) | CT9: =IF(A9="","",$CT$2) | CU9: =IFERROR(VLOOKUP(Procv!Q9,Procv!$C$1:$D$21,2,0),"")
A10: =IF('DADOS CSV'!J11="","",'DADOS CSV'!J11) | B10: =IF('DADOS CSV'!K11="","",'DADOS CSV'!K11) | C10: =IF(A10="","",$C$2) | D10: =IF(A10="","",$D$2) | E10: =IF('DADOS CSV'!L11="","",'DADOS CSV'!L11) | F10: =IF(A10="","",$F$2) | G10: =IF(A10="","",$G$2) | CT10: =IF(A10="","",$CT$2) | CU10: =IFERROR(VLOOKUP(Procv!Q10,Procv!$C$1:$D$21,2,0),"")
A11: =IF('DADOS CSV'!J12="","",'DADOS CSV'!J12) | B11: =IF('DADOS CSV'!K12="","",'DADOS CSV'!K12) | C11: =IF(A11="","",$C$2) | D11: =IF(A11="","",$D$2) | E11: =IF('DADOS CSV'!L12="","",'DADOS CSV'!L12) | F11: =IF(A11="","",$F$2) | G11: =IF(A11="","",$G$2) | CT11: =IF(A11="","",$CT$2) | CU11: =IFERROR(VLOOKUP(Procv!Q11,Procv!$C$1:$D$21,2,0),"")
A12: =IF('DADOS CSV'!J13="","",'DADOS CSV'!J13) | B12: =IF('DADOS CSV'!K13="","",'DADOS CSV'!K13) | C12: =IF(A12="","",$C$2) | D12: =IF(A12="","",$D$2) | E12: =IF('DADOS CSV'!L13="","",'DADOS CSV'!L13) | F12: =IF(A12="","",$F$2) | G12: =IF(A12="","",$G$2) | CT12: =IF(A12="","",$CT$2) | CU12: =IFERROR(VLOOKUP(Procv!Q12,Procv!$C$1:$D$21,2,0),"")
A13: =IF('DADOS CSV'!J14="","",'DADOS CSV'!J14) | B13: =IF('DADOS CSV'!K14="","",'DADOS CSV'!K14) | C13: =IF(A13="","",$C$2) | D13: =IF(A13="","",$D$2) | E13: =IF('DADOS CSV'!L14="","",'DADOS CSV'!L14) | F13: =IF(A13="","",$F$2) | G13: =IF(A13="","",$G$2) | CT13: =IF(A13="","",$CT$2) | CU13: =IFERROR(VLOOKUP(Procv!Q13,Procv!$C$1:$D$21,2,0),"")
A14: =IF('DADOS CSV'!J15="","",'DADOS CSV'!J15) | B14: =IF('DADOS CSV'!K15="","",'DADOS CSV'!K15) | C14: =IF(A14="","",$C$2) | D14: =IF(A14="","",$D$2) | E14: =IF('DADOS CSV'!L15="","",'DADOS CSV'!L15) | F14: =IF(A14="","",$F$2) | G14: =IF(A14="","",$G$2) | CT14: =IF(A14="","",$CT$2) | CU14: =IFERROR(VLOOKUP(Procv!Q14,Procv!$C$1:$D$21,2,0),"")
... A199: =IF('DADOS CSV'!J200="","",'DADOS CSV'!J200) | B199: =IF('DADOS CSV'!K200="","",'DADOS CSV'!K200) | C199: =IF(A199="","",$C$2) | D199: =IF(A199="","",$D$2) | E199: =IF('DADOS CSV'!L200="","",'DADOS CSV'!L200) | F199: =IF(A199="","",$F$2) | G199: =IF(A199="","",$G$2) | CT199: =IF(A199="","",$CT$2) | CU199: =IFERROR(VLOOKUP(Procv!Q199,Procv!$C$1:$D$21,2,0),"")

Sheet CSV VOLTA
A1: Tabela | B1: Horario_Partida | C1: Tolerancia_Atraso1 | D1: Tolerancia_Adiantamento1 | E1: Horario_Chegada | F1: Tolerancia_Atraso2 | G1: Tolerancia_Adiantamento2 | H1: ponto1 | I1: passagem1 | J1: permanencia1 | K1: ponto2 | L1: passagem2 | M1: permanencia2 | N1: ponto3 | O1: passagem3 | P1: permanencia3 | Q1: ponto4 | R1: passagem4 | S1: permanencia4 | T1: ponto5 | U1: passagem5 | V1: permanencia5 | W1: ponto6 | X1: passagem6 | Y1: permanencia6 | Z1: ponto7 | AA1: passagem7 | AB1: permanencia7 | AC1: ponto8 | AD1: passagem8 | AE1: permanencia8 | AF1: ponto9 | AG1: passagem9 | AH1: permanencia9 | AI1: ponto10 | AJ1: passagem10 | AK1: permanencia10 | AL1: ponto11 | AM1: passagem11 | AN1: permanencia11 | AO1: ponto12 | AP1: passagem12 | AQ1: permanencia12 | AR1: ponto13 | AS1: passagem13 | AT1: permanencia13 | AU1: ponto14 | AV1: passagem14 | AW1: permanencia14 | AX1: ponto15 | AY1: passagem15 | AZ1: permanencia15 | BA1: ponto16 | BB1: passagem16 | BC1: permanencia16 | BD1: ponto17 | BE1: passagem17 | BF1: permanencia17 | BG1: ponto18 | BH1: passagem18 | BI1: permanencia18 | BJ1: ponto19 | BK1: passagem19 | BL1: permanencia19 | BM1: ponto20 | BN1: passagem20 | BO1: permanencia20 | BP1: ponto21 | BQ1: passagem21 | BR1: permanencia21 | BS1: ponto22 | BT1: passagem22 | BU1: permanencia22 | BV1: ponto23 | BW1: passagem23 | BX1: permanencia23 | BY1: ponto24 | BZ1: passagem24 | CA1: permanencia24 | CB1: ponto25 | CC1: passagem25 | CD1: permanencia25 | CE1: ponto26 | CF1: passagem26 | CG1: permanencia26 | CH1: ponto27 | CI1: passagem27 | CJ1: permanencia27 | CK1: ponto28 | CL1: passagem28 | CM1: permanencia28 | CN1: ponto29 | CO1: passagem29 | CP1: permanencia29 | CQ1: ponto30 | CR1: passagem30 | CS1: permanencia30 | CT1: empresa | CU1: cod_modelo_veiculo
A2: =IF('DADOS CSV'!J3="","",'DADOS CSV'!J3) -> .1 | B2: =IF('DADOS CSV'!N3="","",'DADOS CSV'!N3) | C2: 10 | D2: 5 | E2: =IF('DADOS CSV'!O3="","",'DADOS CSV'!O3) | F2: 15 | G2: 10 | CT2: XXX | CU2: =IFERROR(VLOOKUP(Procv!R2,Procv!$C$1:$D$21,2,0),"")
A3: =IF('DADOS CSV'!J4="","",'DADOS CSV'!J4) | B3: =IF('DADOS CSV'!N4="","",'DADOS CSV'!N4) | C3: =IF(A3="","",$C$2) | D3: =IF(A3="","",$D$2) | E3: =IF('DADOS CSV'!O4="","",'DADOS CSV'!O4) | F3: =IF(A3="","",$F$2) | G3: =IF(A3="","",$G$2) | CT3: =IF(A3="","",$CT$2) | CU3: =IFERROR(VLOOKUP(Procv!R3,Procv!$C$1:$D$21,2,0),"")
A4: =IF('DADOS CSV'!J5="","",'DADOS CSV'!J5) | B4: =IF('DADOS CSV'!N5="","",'DADOS CSV'!N5) | C4: =IF(A4="","",$C$2) | D4: =IF(A4="","",$D$2) | E4: =IF('DADOS CSV'!O5="","",'DADOS CSV'!O5) | F4: =IF(A4="","",$F$2) | G4: =IF(A4="","",$G$2) | CT4: =IF(A4="","",$CT$2) | CU4: =IFERROR(VLOOKUP(Procv!R4,Procv!$C$1:$D$21,2,0),"")
A5: =IF('DADOS CSV'!J6="","",'DADOS CSV'!J6) | B5: =IF('DADOS CSV'!N6="","",'DADOS CSV'!N6) | C5: =IF(A5="","",$C$2) | D5: =IF(A5="","",$D$2) | E5: =IF('DADOS CSV'!O6="","",'DADOS CSV'!O6) | F5: =IF(A5="","",$F$2) | G5: =IF(A5="","",$G$2) | CT5: =IF(A5="","",$CT$2) | CU5: =IFERROR(VLOOKUP(Procv!R5,Procv!$C$1:$D$21,2,0),"")
A6: =IF('DADOS CSV'!J7="","",'DADOS CSV'!J7) | B6: =IF('DADOS CSV'!N7="","",'DADOS CSV'!N7) | C6: =IF(A6="","",$C$2) | D6: =IF(A6="","",$D$2) | E6: =IF('DADOS CSV'!O7="","",'DADOS CSV'!O7) | F6: =IF(A6="","",$F$2) | G6: =IF(A6="","",$G$2) | CT6: =IF(A6="","",$CT$2) | CU6: =IFERROR(VLOOKUP(Procv!R6,Procv!$C$1:$D$21,2,0),"")
A7: =IF('DADOS CSV'!J8="","",'DADOS CSV'!J8) | B7: =IF('DADOS CSV'!N8="","",'DADOS CSV'!N8) | C7: =IF(A7="","",$C$2) | D7: =IF(A7="","",$D$2) | E7: =IF('DADOS CSV'!O8="","",'DADOS CSV'!O8) | F7: =IF(A7="","",$F$2) | G7: =IF(A7="","",$G$2) | CT7: =IF(A7="","",$CT$2) | CU7: =IFERROR(VLOOKUP(Procv!R7,Procv!$C$1:$D$21,2,0),"")
A8: =IF('DADOS CSV'!J9="","",'DADOS CSV'!J9) | B8: =IF('DADOS CSV'!N9="","",'DADOS CSV'!N9) | C8: =IF(A8="","",$C$2) | D8: =IF(A8="","",$D$2) | E8: =IF('DADOS CSV'!O9="","",'DADOS CSV'!O9) | F8: =IF(A8="","",$F$2) | G8: =IF(A8="","",$G$2) | CT8: =IF(A8="","",$CT$2) | CU8: =IFERROR(VLOOKUP(Procv!R8,Procv!$C$1:$D$21,2,0),"")
A9: =IF('DADOS CSV'!J10="","",'DADOS CSV'!J10) | B9: =IF('DADOS CSV'!N10="","",'DADOS CSV'!N10) | C9: =IF(A9="","",$C$2) | D9: =IF(A9="","",$D$2) | E9: =IF('DADOS CSV'!O10="","",'DADOS CSV'!O10) | F9: =IF(A9="","",$F$2) | G9: =IF(A9="","",$G$2) | CT9: =IF(A9="","",$CT$2) | CU9: =IFERROR(VLOOKUP(Procv!R9,Procv!$C$1:$D$21,2,0),"")
A10: =IF('DADOS CSV'!J11="","",'DADOS CSV'!J11) | B10: =IF('DADOS CSV'!N11="","",'DADOS CSV'!N11) | C10: =IF(A10="","",$C$2) | D10: =IF(A10="","",$D$2) | E10: =IF('DADOS CSV'!O11="","",'DADOS CSV'!O11) | F10: =IF(A10="","",$F$2) | G10: =IF(A10="","",$G$2) | CT10: =IF(A10="","",$CT$2) | CU10: =IFERROR(VLOOKUP(Procv!R10,Procv!$C$1:$D$21,2,0),"")
A11: =IF('DADOS CSV'!J12="","",'DADOS CSV'!J12) | B11: =IF('DADOS CSV'!N12="","",'DADOS CSV'!N12) | C11: =IF(A11="","",$C$2) | D11: =IF(A11="","",$D$2) | E11: =IF('DADOS CSV'!O12="","",'DADOS CSV'!O12) | F11: =IF(A11="","",$F$2) | G11: =IF(A11="","",$G$2) | CT11: =IF(A11="","",$CT$2) | CU11: =IFERROR(VLOOKUP(Procv!R11,Procv!$C$1:$D$21,2,0),"")
A12: =IF('DADOS CSV'!J13="","",'DADOS CSV'!J13) | B12: =IF('DADOS CSV'!N13="","",'DADOS CSV'!N13) | C12: =IF(A12="","",$C$2) | D12: =IF(A12="","",$D$2) | E12: =IF('DADOS CSV'!O13="","",'DADOS CSV'!O13) | F12: =IF(A12="","",$F$2) | G12: =IF(A12="","",$G$2) | CT12: =IF(A12="","",$CT$2) | CU12: =IFERROR(VLOOKUP(Procv!R12,Procv!$C$1:$D$21,2,0),"")
A13: =IF('DADOS CSV'!J14="","",'DADOS CSV'!J14) | B13: =IF('DADOS CSV'!N14="","",'DADOS CSV'!N14) | C13: =IF(A13="","",$C$2) | D13: =IF(A13="","",$D$2) | E13: =IF('DADOS CSV'!O14="","",'DADOS CSV'!O14) | F13: =IF(A13="","",$F$2) | G13: =IF(A13="","",$G$2) | CT13: =IF(A13="","",$CT$2) | CU13: =IFERROR(VLOOKUP(Procv!R13,Procv!$C$1:$D$21,2,0),"")
A14: =IF('DADOS CSV'!J15="","",'DADOS CSV'!J15) | B14: =IF('DADOS CSV'!N15="","",'DADOS CSV'!N15) | C14: =IF(A14="","",$C$2) | D14: =IF(A14="","",$D$2) | E14: =IF('DADOS CSV'!O15="","",'DADOS CSV'!O15) | F14: =IF(A14="","",$F$2) | G14: =IF(A14="","",$G$2) | CT14: =IF(A14="","",$CT$2) | CU14: =IFERROR(VLOOKUP(Procv!R14,Procv!$C$1:$D$21,2,0),"")
... A199: =IF('DADOS CSV'!J200="","",'DADOS CSV'!J200) | B199: =IF('DADOS CSV'!N200="","",'DADOS CSV'!N200) | C199: =IF(A199="","",$C$2) | D199: =IF(A199="","",$D$2) | E199: =IF('DADOS CSV'!O200="","",'DADOS CSV'!O200) | F199: =IF(A199="","",$F$2) | G199: =IF(A199="","",$G$2) | CT199: =IF(A199="","",$CT$2) | CU199: =IFERROR(VLOOKUP(Procv!R199,Procv!$C$1:$D$21,2,0),"")

Sheet F U
A1: Nº Ordem | B1: 1º Turno | D1: 2º Turno | F1: Jorna | G1: Desloc | I1: 1 | J1: 1.0416667 | K1: 1.0833333 | L1: 1.125 | M1: 0.16666667 | N1: 0.20833333 | O1: 0.25 | P1: 0.29166667 | Q1: 0.33333333 | R1: 0.375 | S1: 0.41666667 | T1: 0.45833333 | U1: 0.5 | V1: 0.54166667 | W1: 0.58333333 | X1: 0.625 | Y1: 0.66666667 | Z1: 0.70833333 | AA1: 0.75 | AB1: 0.79166667 | AC1: 0.83333333 | AD1: 0.875 | AE1: 0.91666667 | AF1: 0.95833333
B2: Inicio | C2: Término | D2: Inicio | E2: Término | I2: =COUNTIF(I3:I72,"X") -> 0 | J2: =COUNTIF(J3:J72,"X") -> 0 | K2: =COUNTIF(K3:K72,"X") -> 0 | L2: =COUNTIF(L3:L72,"X") -> 0 | M2: =COUNTIF(M3:M72,"X") -> 0 | N2: =COUNTIF(N3:N72,"X") -> 0 | O2: =COUNTIF(O3:O72,"X") -> 0 | P2: =COUNTIF(P3:P72,"X") -> 0 | ... AF2: =COUNTIF(AF3:AF72,"X") -> 0
A3: =IF(B3>=0.000694444444444444,1,"") -> #REF! | B3: =MIN(#REF!)-G3 -> #REF! | C3: =IF(MIN(#REF!)>0.08333,OFFSET(#REF!,MATCH(MIN(#REF!),#REF!,0),-4),MAX(#REF!)) -> #REF! | D3: =IF(MIN(#REF!)>0.08333,OFFSET(#REF!,MATCH(MIN(#REF!),#REF!,0),-2),MIN(#REF!)) -> #REF! | E3: =IF(MIN(#REF!)>0.08333,MAX(#REF!),MAX(#REF!))+G3 -> #REF! | F3: =E3-B3 -> #REF! | G3: 0 | I3: =IF(AND(J$1-$B3>=0.0208333,$C3-I$1>0.0208333),"X",IF(AND(J$1-$D3>=0.0208333,$E3-I$1>0.0208333),"X",IF(MROUND($C3,"01:00")=I$1,IF(J$1-$D3+$C3-I$1>=0.02083,"X",""),""))) -> #REF! | J3: =IF(AND(K$1-$B3>=0.0208333,$C3-J$1>0.0208333),"X",IF(AND(K$1-$D3>=0.0208333,$E3-J$1>0.0208333),"X",IF(MROUND($C3,"01:00")=J$1,IF(K$1-$D3+$C3-J$1>=0.02083,"X",""),""))) -> #REF! | K3: =IF(AND(L$1-$B3>=0.0208333,$C3-K$1>0.0208333),"X",IF(AND(L$1-$D3>=0.0208333,$E3-K$1>0.0208333),"X",IF(MROUND($C3,"01:00")=K$1,IF(L$1-$D3+$C3-K$1>=0.02083,"X",""),""))) -> #REF! | L3: =IF(AND(M$1-$B3>=0.0208333,$C3-L$1>0.0208333),"X",IF(AND(M$1-$D3>=0.0208333,$E3-L$1>0.0208333),"X",IF(MROUND($C3,"01:00")=L$1,IF(M$1-$D3+$C3-L$1>=0.02083,"X",""),""))) -> #REF! | M3: =IF(AND(N$1-$B3>=0.0208333,$C3-M$1>0.0208333),"X",IF(AND(N$1-$D3>=0.0208333,$E3-M$1>0.0208333),"X",IF(MROUND($C3,"01:00")=M$1,IF(N$1-$D3+$C3-M$1>=0.02083,"X",""),""))) -> #REF! | N3: =IF(AND(O$1-$B3>=0.0208333,$C3-N$1>0.0208333),"X",IF(AND(O$1-$D3>=0.0208333,$E3-N$1>0.0208333),"X",IF(MROUND($C3,"01:00")=N$1,IF(O$1-$D3+$C3-N$1>=0.02083,"X",""),""))) -> #REF! | O3: =IF(AND(P$1-$B3>=0.0208333,$C3-O$1>0.0208333),"X",IF(AND(P$1-$D3>=0.0208333,$E3-O$1>0.0208333),"X",IF(MROUND($C3,"01:00")=O$1,IF(P$1-$D3+$C3-O$1>=0.02083,"X",""),""))) -> #REF! | P3: =IF(AND(Q$1-$B3>=0.0208333,$C3-P$1>0.0208333),"X",IF(AND(Q$1-$D3>=0.0208333,$E3-P$1>0.0208333),"X",IF(MROUND($C3,"01:00")=P$1,IF(Q$1-$D3+$C3-P$1>=0.02083,"X",""),""))) -> #REF! | ... AF3: =IF(AND(AG$1-$B3>=0.0208333,$C3-AF$1>0.0208333),"X",IF(AND(AG$1-$D3>=0.0208333,$E3-AF$1>0.0208333),"X",IF(MROUND($C3,"01:00")=AF$1,IF(AG$1-$D3+$C3-AF$1>=0.02083,"X",""),""))) -> #REF!
A4: =IF(B4>0,1+A3,"") -> #REF! | B4: =MIN(#REF!)-G3 -> #REF! | C4: =IF(MIN(#REF!)>0.08333,OFFSET(#REF!,MATCH(MIN(#REF!),#REF!,0),-4),MAX(#REF!)) -> #REF! | D4: =IF(MIN(#REF!)>0.08333,OFFSET(#REF!,MATCH(MIN(#REF!),#REF!,0),-2),MIN(#REF!)) -> #REF! | E4: =IF(MIN(#REF!)>0.08333,MAX(#REF!),MAX(#REF!))+G3 -> #REF! | F4: =E4-B4 -> #REF! | I4: =IF(AND(J$1-$B4>=0.0208333,$C4-I$1>0.0208333),"X",IF(AND(J$1-$D4>=0.0208333,$E4-I$1>0.0208333),"X",IF(MROUND($C4,"01:00")=I$1,IF(J$1-$D4+$C4-I$1>=0.02083,"X",""),""))) -> #REF! | J4: =IF(AND(K$1-$B4>=0.0208333,$C4-J$1>0.0208333),"X",IF(AND(K$1-$D4>=0.0208333,$E4-J$1>0.0208333),"X",IF(MROUND($C4,"01:00")=J$1,IF(K$1-$D4+$C4-J$1>=0.02083,"X",""),""))) -> #REF! | K4: =IF(AND(L$1-$B4>=0.0208333,$C4-K$1>0.0208333),"X",IF(AND(L$1-$D4>=0.0208333,$E4-K$1>0.0208333),"X",IF(MROUND($C4,"01:00")=K$1,IF(L$1-$D4+$C4-K$1>=0.02083,"X",""),""))) -> #REF! | L4: =IF(AND(M$1-$B4>=0.0208333,$C4-L$1>0.0208333),"X",IF(AND(M$1-$D4>=0.0208333,$E4-L$1>0.0208333),"X",IF(MROUND($C4,"01:00")=L$1,IF(M$1-$D4+$C4-L$1>=0.02083,"X",""),""))) -> #REF! | M4: =IF(AND(N$1-$B4>=0.0208333,$C4-M$1>0.0208333),"X",IF(AND(N$1-$D4>=0.0208333,$E4-M$1>0.0208333),"X",IF(MROUND($C4,"01:00")=M$1,IF(N$1-$D4+$C4-M$1>=0.02083,"X",""),""))) -> #REF! | N4: =IF(AND(O$1-$B4>=0.0208333,$C4-N$1>0.0208333),"X",IF(AND(O$1-$D4>=0.0208333,$E4-N$1>0.0208333),"X",IF(MROUND($C4,"01:00")=N$1,IF(O$1-$D4+$C4-N$1>=0.02083,"X",""),""))) -> #REF! | O4: =IF(AND(P$1-$B4>=0.0208333,$C4-O$1>0.0208333),"X",IF(AND(P$1-$D4>=0.0208333,$E4-O$1>0.0208333),"X",IF(MROUND($C4,"01:00")=O$1,IF(P$1-$D4+$C4-O$1>=0.02083,"X",""),""))) -> #REF! | P4: =IF(AND(Q$1-$B4>=0.0208333,$C4-P$1>0.0208333),"X",IF(AND(Q$1-$D4>=0.0208333,$E4-P$1>0.0208333),"X",IF(MROUND($C4,"01:00")=P$1,IF(Q$1-$D4+$C4-P$1>=0.02083,"X",""),""))) -> #REF! | ... AF4: =IF(AND(AG$1-$B4>=0.0208333,$C4-AF$1>0.0208333),"X",IF(AND(AG$1-$D4>=0.0208333,$E4-AF$1>0.0208333),"X",IF(MROUND($C4,"01:00")=AF$1,IF(AG$1-$D4+$C4-AF$1>=0.02083,"X",""),""))) -> #REF!
A5: =IF(B5>0,1+A4,"") -> #REF! | B5: =MIN(#REF!)-G3 -> #REF! | C5: =IF(MIN(#REF!)>0.08333,OFFSET(#REF!,MATCH(MIN(#REF!),#REF!,0),-4),MAX(#REF!)) -> #REF! | D5: =IF(MIN(#REF!)>0.08333,OFFSET(#REF!,MATCH(MIN(#REF!),#REF!,0),-2),MIN(#REF!)) -> #REF! | E5: =IF(MIN(#REF!)>0.08333,MAX(#REF!),MAX(#REF!))+G3 -> #REF! | F5: =E5-B5 -> #REF! | I5: =IF(AND(J$1-$B5>=0.0208333,$C5-I$1>0.0208333),"X",IF(AND(J$1-$D5>=0.0208333,$E5-I$1>0.0208333),"X",IF(MROUND($C5,"01:00")=I$1,IF(J$1-$D5+$C5-I$1>=0.02083,"X",""),""))) -> #REF! | J5: =IF(AND(K$1-$B5>=0.0208333,$C5-J$1>0.0208333),"X",IF(AND(K$1-$D5>=0.0208333,$E5-J$1>0.0208333),"X",IF(MROUND($C5,"01:00")=J$1,IF(K$1-$D5+$C5-J$1>=0.02083,"X",""),""))) -> #REF! | K5: =IF(AND(L$1-$B5>=0.0208333,$C5-K$1>0.0208333),"X",IF(AND(L$1-$D5>=0.0208333,$E5-K$1>0.0208333),"X",IF(MROUND($C5,"01:00")=K$1,IF(L$1-$D5+$C5-K$1>=0.02083,"X",""),""))) -> #REF! | L5: =IF(AND(M$1-$B5>=0.0208333,$C5-L$1>0.0208333),"X",IF(AND(M$1-$D5>=0.0208333,$E5-L$1>0.0208333),"X",IF(MROUND($C5,"01:00")=L$1,IF(M$1-$D5+$C5-L$1>=0.02083,"X",""),""))) -> #REF! | M5: =IF(AND(N$1-$B5>=0.0208333,$C5-M$1>0.0208333),"X",IF(AND(N$1-$D5>=0.0208333,$E5-M$1>0.0208333),"X",IF(MROUND($C5,"01:00")=M$1,IF(N$1-$D5+$C5-M$1>=0.02083,"X",""),""))) -> #REF! | N5: =IF(AND(O$1-$B5>=0.0208333,$C5-N$1>0.0208333),"X",IF(AND(O$1-$D5>=0.0208333,$E5-N$1>0.0208333),"X",IF(MROUND($C5,"01:00")=N$1,IF(O$1-$D5+$C5-N$1>=0.02083,"X",""),""))) -> #REF! | O5: =IF(AND(P$1-$B5>=0.0208333,$C5-O$1>0.0208333),"X",IF(AND(P$1-$D5>=0.0208333,$E5-O$1>0.0208333),"X",IF(MROUND($C5,"01:00")=O$1,IF(P$1-$D5+$C5-O$1>=0.02083,"X",""),""))) -> #REF! | P5: =IF(AND(Q$1-$B5>=0.0208333,$C5-P$1>0.0208333),"X",IF(AND(Q$1-$D5>=0.0208333,$E5-P$1>0.0208333),"X",IF(MROUND($C5,"01:00")=P$1,IF(Q$1-$D5+$C5-P$1>=0.02083,"X",""),""))) -> #REF! | ... AF5: =IF(AND(AG$1-$B5>=0.0208333,$C5-AF$1>0.0208333),"X",IF(AND(AG$1-$D5>=0.0208333,$E5-AF$1>0.0208333),"X",IF(MROUND($C5,"01:00")=AF$1,IF(AG$1-$D5+$C5-AF$1>=0.02083,"X",""),""))) -> #REF!
